Workbook

Sheet Final
A1: Product Name | B1: Product Name | C1: Category | D1: 3 month revenue | E1: MRP Including GST | F1: MRP without GST | G1: Returns | H1: Discounts | I1: Net Revenue | J1: Cost of Material | K1: Gross margin | L1: Packaging Secondary | M1: Razorpay Deduction | N1: Shipping to Customer | O1: COD Costs | P1: CM 1 | Q1: Marketing Cost | R1: Units sold | S1: CM 2 | T1: CM 2 % | U1: Overheads | V1: EBIDTA | W1: EBIDTA %
A2: magic paint dust | B2: Magic Paint Dust – Baby’s First Painting Kit | C2: Magic paint dust | D2: {=XLOOKUP(B2,'Calculations As per GA Data'!B20:B141,'Calculations As per GA Data'!G20:G141)} -> 192044 | E2: 899 | F2: =E2/1.18 -> 761.86441 | G2: 4.75 | H2: {=XLOOKUP(B2,'Discount calculation'!A:A,'Discount calculation'!D:D)} -> 11.111156 | I2: =F2-SUM(G2:H2) -> 746.00325 | J2: 126.3 | K2: =I2-J2 -> 619.70325 | L2: 12.5 | M2: 7.52 | N2: 150.51244 | O2: 4.55 | P2: =K2-SUM(L2:O2) -> 444.62081 | Q2: {=XLOOKUP(B2,'Calculations As per GA Data'!B20:B141,'Calculations As per GA Data'!J20:J141)} -> 1098.7847 | R2: {=XLOOKUP(B2,'Calculations As per GA Data'!B20:B141,'Calculations As per GA Data'!F20:F141)} -> 221 | S2: =P2-Q2 -> -654.16393 | T2: =S2/I2 -> -0.87689153 | U2: 229 | V2: =S2-U2 -> -883.16393 | W2: =V2/I2 -> -1.1838607
A3: Playdough | B3: dabble Sensory Playdough | C3: Playdough | D3: {=XLOOKUP(B3,'Calculations As per GA Data'!B21:B142,'Calculations As per GA Data'!G21:G142)} -> 190336 | E3: 899 | F3: =E3/1.18 -> 761.86441 | G3: 4.75 | H3: {=XLOOKUP(B3,'Discount calculation'!A:A,'Discount calculation'!D:D)} -> 11.273119 | I3: =F3-SUM(G3:H3) -> 745.84129 | J3: 124.49 | K3: =I3-J3 -> 621.35129 | L3: 12.5 | M3: 7.52 | N3: 167.52374 | O3: 4.55 | P3: =K3-SUM(L3:O3) -> 429.25755 | Q3: {=XLOOKUP(B3,'Calculations As per GA Data'!B21:B142,'Calculations As per GA Data'!J21:J142)} -> 1038.5119 | R3: {=XLOOKUP(B3,'Calculations As per GA Data'!B21:B142,'Calculations As per GA Data'!F21:F142)} -> 214 | S3: =P3-Q3 -> -609.25437 | T3: =S3/I3 -> -0.81686866 | U3: 229 | V3: =S3-U3 -> -838.25437 | W3: =V3/I3 -> -1.1239045
A4: FP8+CB | B4: Dabble Finger Painting Fun Pack | C4: Combo | D4: {=XLOOKUP(B4,'Calculations As per GA Data'!B22:B143,'Calculations As per GA Data'!G22:G143)} -> 157681 | E4: 1348 | F4: =E4/1.18 -> 1142.3729 | G4: 4.75 | H4: {=XLOOKUP(B4,'Discount calculation'!A:A,'Discount calculation'!D:D)} -> 17.370523 | I4: =F4-SUM(G4:H4) -> 1120.2524 | J4: 238.12 | K4: =I4-J4 -> 882.13236 | L4: 14.5 | M4: 7.52 | N4: 189.105 | O4: 4.55 | P4: =K4-SUM(L4:O4) -> 666.45736 | Q4: {=XLOOKUP(B4,'Calculations As per GA Data'!B22:B143,'Calculations As per GA Data'!J22:J143)} -> 651.96262 | R4: {=XLOOKUP(B4,'Calculations As per GA Data'!B22:B143,'Calculations As per GA Data'!F22:F143)} -> 122 | S4: =P4-Q4 -> 14.494743 | T4: =S4/I4 -> 0.012938819 | U4: 229 | V4: =S4-U4 -> -214.50526 | W4: =V4/I4 -> -0.19147941
A5: Canvas Kit | B5: Babyâ€™s first handprint and footprint kit | C5: Canvas Kit | D5: {=XLOOKUP(B5,'Calculations As per GA Data'!B23:B144,'Calculations As per GA Data'!G23:G144)} -> 113540 | E5: 649 | F5: =E5/1.18 -> 550 | G5: 4.75 | H5: {=XLOOKUP(B5,'Discount calculation'!A:A,'Discount calculation'!D:D)} -> 8.1738809 | I5: =F5-SUM(G5:H5) -> 537.07612 | J5: 70.1 | K5: =I5-J5 -> 466.97612 | L5: 12.5 | M5: 7.52 | N5: 171.34694 | O5: 4.55 | P5: =K5-SUM(L5:O5) -> 271.05918 | Q5: {=XLOOKUP(B5,'Calculations As per GA Data'!B23:B144,'Calculations As per GA Data'!J23:J144)} -> 1115.285 | R5: {=XLOOKUP(B5,'Calculations As per GA Data'!B23:B144,'Calculations As per GA Data'!F23:F144)} -> 160 | S5: =P5-Q5 -> -844.22578 | T5: =S5/I5 -> -1.5718922 | U5: 229 | V5: =S5-U5 -> -1073.2258 | W5: =V5/I5 -> -1.998275
A6: SFP | B6: Mini Starter Finger Painting Fun Pack | C6: SFP | D6: {=XLOOKUP(B6,'Calculations As per GA Data'!B24:B145,'Calculations As per GA Data'!G24:G145)} -> 101319 | E6: 599 | F6: =E6/1.18 -> 507.62712 | G6: 4.75 | H6: {=XLOOKUP(B6,'Discount calculation'!A:A,'Discount calculation'!D:D)} -> 6.5260964 | I6: =F6-SUM(G6:H6) -> 496.35102 | J6: 89.33 | K6: =I6-J6 -> 407.02102 | L6: 6.5 | M6: 7.52 | N6: 176.04228 | O6: 4.55 | P6: =K6-SUM(L6:O6) -> 212.40874 | Q6: {=XLOOKUP(B6,'Calculations As per GA Data'!B24:B145,'Calculations As per GA Data'!J24:J145)} -> 460.17557 | R6: {=XLOOKUP(B6,'Calculations As per GA Data'!B24:B145,'Calculations As per GA Data'!F24:F145)} -> 171 | S6: =P6-Q6 -> -247.76682 | T6: =S6/I6 -> -0.49917662 | U6: 229 | V6: =S6-U6 -> -476.76682 | W6: =V6/I6 -> -0.96054365
A7: SFP+JB | B7: Babyâ€™s Starter Painting + Jumbo Brush Combo Kit | C7: Combo | D7: {=XLOOKUP(B7,'Calculations As per GA Data'!B25:B146,'Calculations As per GA Data'!G25:G146)} -> 79281 | E7: 1098 | F7: =E7/1.18 -> 930.50847 | G7: 4.75 | H7: {=XLOOKUP(B7,'Discount calculation'!A:A,'Discount calculation'!D:D)} -> 12.236439 | I7: =F7-SUM(G7:H7) -> 913.52204 | J7: 117.5 | K7: =I7-J7 -> 796.02204 | L7: 11.5 | M7: 7.52 | N7: 153.54427 | O7: 4.55 | P7: =K7-SUM(L7:O7) -> 618.90777 | Q7: {=XLOOKUP(B7,'Calculations As per GA Data'!B25:B146,'Calculations As per GA Data'!J25:J146)} -> 477.93882 | R7: {=XLOOKUP(B7,'Calculations As per GA Data'!B25:B146,'Calculations As per GA Data'!F25:F146)} -> 75 | S7: =P7-Q7 -> 140.96895 | T7: =S7/I7 -> 0.15431368 | U7: 229 | V7: =S7-U7 -> -88.03105 | W7: =V7/I7 -> -0.096364452
A8: B3 | B8: Dabble Playart Chunkies | C8: Caryons | D8: {=XLOOKUP(B8,'Calculations As per GA Data'!B26:B147,'Calculations As per GA Data'!G26:G147)} -> 70820.999 | E8: 549 | F8: =E8/1.18 -> 465.25424 | G8: 4.75 | H8: {=XLOOKUP(B8,'Discount calculation'!A:A,'Discount calculation'!D:D)} -> 6.0704762 | I8: =F8-SUM(G8:H8) -> 454.43376 | J8: 65.5 | K8: =I8-J8 -> 388.93376 | L8: 5 | M8: 7.52 | N8: 96.507674 | O8: 4.55 | P8: =K8-SUM(L8:O8) -> 275.35609 | Q8: {=XLOOKUP(B8,'Calculations As per GA Data'!B26:B147,'Calculations As per GA Data'!J26:J147)} -> 914.47348 | R8: {=XLOOKUP(B8,'Calculations As per GA Data'!B26:B147,'Calculations As per GA Data'!F26:F147)} -> 129 | S8: =P8-Q8 -> -639.1174 | T8: =S8/I8 -> -1.4064039 | U8: 229 | V8: =S8-U8 -> -868.1174 | W8: =V8/I8 -> -1.9103277
A9: FP8, B8, CB | B9: Little Artist Combo Kit | C9: Combo | D9: {=XLOOKUP(B9,'Calculations As per GA Data'!B27:B148,'Calculations As per GA Data'!G27:G148)} -> 81477 | E9: 1797 | F9: =E9/1.18 -> 1522.8814 | G9: 4.75 | H9: {=XLOOKUP(B9,'Discount calculation'!A:A,'Discount calculation'!D:D)} -> 30.1056 | I9: =F9-SUM(G9:H9) -> 1488.0258 | J9: 254.99 | K9: =I9-J9 -> 1233.0358 | L9: 19.5 | M9: 7.52 | N9: 170.99915 | O9: 4.55 | P9: =K9-SUM(L9:O9) -> 1030.4666 | Q9: {=XLOOKUP(B9,'Calculations As per GA Data'!B27:B148,'Calculations As per GA Data'!J27:J148)} -> 804.59701 | R9: {=XLOOKUP(B9,'Calculations As per GA Data'!B27:B148,'Calculations As per GA Data'!F27:F148)} -> 47 | S9: =P9-Q9 -> 225.86959 | T9: =S9/I9 -> 0.15179145 | U9: 229 | V9: =S9-U9 -> -3.1304073 | W9: =V9/I9 -> -0.002103732
A10: SFP+CB | B10: Dabble Starter Painting + Chubby Brush Combo Kit | C10: Combo | D10: {=XLOOKUP(B10,'Calculations As per GA Data'!B28:B149,'Calculations As per GA Data'!G28:G149)} -> 90842 | E10: 1048 | F10: =E10/1.18 -> 888.13559 | G10: 4.75 | H10: {=XLOOKUP(B10,'Discount calculation'!A:A,'Discount calculation'!D:D)} -> 11.805471 | I10: =F10-SUM(G10:H10) -> 871.58012 | J10: 165.73 | K10: =I10-J10 -> 705.85012 | L10: 11.5 | M10: 7.52 | N10: 142.47578 | O10: 4.55 | P10: =K10-SUM(L10:O10) -> 539.80434 | Q10: {=XLOOKUP(B10,'Calculations As per GA Data'!B28:B149,'Calculations As per GA Data'!J28:J149)} -> 503.23258 | R10: {=XLOOKUP(B10,'Calculations As per GA Data'!B28:B149,'Calculations As per GA Data'!F28:F149)} -> 90 | S10: =P10-Q10 -> 36.571765 | T10: =S10/I10 -> 0.041960301 | U10: 229 | V10: =S10-U10 -> -192.42824 | W10: =V10/I10 -> -0.22078089
A11: FP3 | B11: Dabble Finger Paints For Toddlers | C11: FP3 | D11: {=XLOOKUP(B11,'Calculations As per GA Data'!B29:B150,'Calculations As per GA Data'!G29:G150)} -> 63589 | E11: 649 | F11: =E11/1.18 -> 550 | G11: 4.75 | H11: {=XLOOKUP(B11,'Discount calculation'!A:A,'Discount calculation'!D:D)} -> 9.4861538 | I11: =F11-SUM(G11:H11) -> 535.76385 | J11: 62.96 | K11: =I11-J11 -> 472.80385 | L11: 6.5 | M11: 7.52 | N11: 139.41584 | O11: 4.55 | P11: =K11-SUM(L11:O11) -> 314.818 | Q11: {=XLOOKUP(B11,'Calculations As per GA Data'!B29:B150,'Calculations As per GA Data'!J29:J150)} -> 478.36493 | R11: {=XLOOKUP(B11,'Calculations As per GA Data'!B29:B150,'Calculations As per GA Data'!F29:F150)} -> 101 | S11: =P11-Q11 -> -163.54693 | T11: =S11/I11 -> -0.30525935 | U11: 229 | V11: =S11-U11 -> -392.54693 | W11: =V11/I11 -> -0.73268648
A12: AR | B12: Dabble Art Roll | C12: AR | D12: {=XLOOKUP(B12,'Calculations As per GA Data'!B30:B151,'Calculations As per GA Data'!G30:G151)} -> 50328 | E12: 699 | F12: =E12/1.18 -> 592.37288 | G12: 4.75 | H12: {=XLOOKUP(B12,'Discount calculation'!A:A,'Discount calculation'!D:D)} -> 9.6347942 | I12: =F12-SUM(G12:H12) -> 577.98809 | J12: 131 | K12: =I12-J12 -> 446.98809 | L12: 8.5 | M12: 7.52 | N12: 145.18389 | O12: 4.55 | P12: =K12-SUM(L12:O12) -> 281.2342 | Q12: {=XLOOKUP(B12,'Calculations As per GA Data'!B30:B151,'Calculations As per GA Data'!J30:J151)} -> 338.82314 | R12: {=XLOOKUP(B12,'Calculations As per GA Data'!B30:B151,'Calculations As per GA Data'!F30:F151)} -> 72 | S12: =P12-Q12 -> -57.588938 | T12: =S12/I12 -> -0.099636894 | U12: 229 | V12: =S12-U12 -> -286.58894 | W12: =V12/I12 -> -0.49583883
A13: magic paint dust+jb | B13: Magic Paint Dust + Jumbo Brush Combo Kit â€“ Babyâ€™s First Painting Kit | C13: Combo | D13: {=XLOOKUP(B13,'Calculations As per GA Data'!B31:B152,'Calculations As per GA Data'!G31:G152)} -> 45782 | E13: 1398 | F13: =E13/1.18 -> 1184.7458 | G13: 4.75 | H13: {=XLOOKUP(B13,'Discount calculation'!A:A,'Discount calculation'!D:D)} -> 22.653765 | I13: =F13-SUM(G13:H13) -> 1157.342 | J13: 182 | K13: =I13-J13 -> 975.342 | L13: 17.5 | M13: 7.52 | N13: 145.05882 | O13: 4.55 | P13: =K13-SUM(L13:O13) -> 800.71317 | Q13: {=XLOOKUP(B13,'Calculations As per GA Data'!B31:B152,'Calculations As per GA Data'!J31:J152)} -> 966.33713 | R13: {=XLOOKUP(B13,'Calculations As per GA Data'!B31:B152,'Calculations As per GA Data'!F31:F152)} -> 34 | S13: =P13-Q13 -> -165.62396 | T13: =S13/I13 -> -0.14310719 | U13: 229 | V13: =S13-U13 -> -394.62396 | W13: =V13/I13 -> -0.34097437
... A19: Apron | B19: Dabble Painting Art Apron | C19: Apron | D19: {=XLOOKUP(B19,'Calculations As per GA Data'!B37:B158,'Calculations As per GA Data'!G37:G158)} -> 38751.5 | E19: 799 | F19: =E19/1.18 -> 677.11864 | G19: 4.75 | H19: {=XLOOKUP(B19,'Discount calculation'!A:A,'Discount calculation'!D:D)} -> 12.823761 | I19: =F19-SUM(G19:H19) -> 659.54488 | J19: 215.5 | K19: =I19-J19 -> 444.04488 | L19: 5 | M19: 7.52 | N19: 109.919 | O19: 4.55 | P19: =K19-SUM(L19:O19) -> 317.05588 | Q19: {=XLOOKUP(B19,'Calculations As per GA Data'!B37:B158,'Calculations As per GA Data'!J37:J158)} -> 322.77859 | R19: {=XLOOKUP(B19,'Calculations As per GA Data'!B37:B158,'Calculations As per GA Data'!F37:F158)} -> 50 | S19: =P19-Q19 -> -5.722704 | T19: =S19/I19 -> -0.0086767469 | U19: 229 | V19: =S19-U19 -> -234.7227 | W19: =V19/I19 -> -0.35588587
A20: ABC Kit | B20: My Dabble ABC Trace & Colour Kit | Multi-Sensory Alphabet Learning for Kids | C20: ABC Kit | D20: {=XLOOKUP(B20,'Calculations As per GA Data'!B38:B159,'Calculations As per GA Data'!G38:G159)} -> 58561.999 | E20: 699 | F20: =E20/1.18 -> 592.37288 | G20: 4.75 | H20: {=XLOOKUP(B20,'Discount calculation'!A:A,'Discount calculation'!D:D)} -> 7.1620459 | I20: =F20-SUM(G20:H20) -> 580.46084 | J20: 105 | K20: =I20-J20 -> 475.46084 | L20: 8.5 | M20: 7.52 | N20: NA | O20: 4.55 | P20: =K20-SUM(L20:O20) -> 454.89084 | Q20: {=XLOOKUP(B20,'Calculations As per GA Data'!B38:B159,'Calculations As per GA Data'!J38:J159)} -> 857.39146 | R20: {=XLOOKUP(B20,'Calculations As per GA Data'!B38:B159,'Calculations As per GA Data'!F38:F159)} -> 98 | S20: =P20-Q20 -> -402.50062 | T20: =S20/I20 -> -0.69341564 | U20: 229 | V20: =S20-U20 -> -631.50062 | W20: =V20/I20 -> -1.0879298
A21: FP8 | B21: Dabble Playart Finger Paints | C21: FP8 | D21: {=XLOOKUP(B21,'Calculations As per GA Data'!B39:B160,'Calculations As per GA Data'!G39:G160)} -> 53295 | E21: 899 | F21: =E21/1.18 -> 761.86441 | G21: 4.75 | H21: {=XLOOKUP(B21,'Discount calculation'!A:A,'Discount calculation'!D:D)} -> 11.633624 | I21: =F21-SUM(G21:H21) -> 745.48078 | J21: 117.7 | K21: =I21-J21 -> 627.78078 | L21: 9.5 | M21: 7.52 | N21: 198.64467 | O21: 4.55 | P21: =K21-SUM(L21:O21) -> 407.56612 | Q21: {=XLOOKUP(B21,'Calculations As per GA Data'!B39:B160,'Calculations As per GA Data'!J39:J160)} -> 460.95047 | R21: {=XLOOKUP(B21,'Calculations As per GA Data'!B39:B160,'Calculations As per GA Data'!F39:F160)} -> 60 | S21: =P21-Q21 -> -53.384357 | T21: =S21/I21 -> -0.071610642 | U21: 229 | V21: =S21-U21 -> -282.38436 | W21: =V21/I21 -> -0.37879495
A22: Playdough+MPD | B22: Imagination Spark Kit | Dabble Sensory Play Dough + Magic Paint Dust | C22: Combo | D22: {=XLOOKUP(B22,'Calculations As per GA Data'!B40:B161,'Calculations As per GA Data'!G40:G161)} -> 19004 | E22: 1798 | F22: =E22/1.18 -> 1523.7288 | G22: 4.75 | H22: {=XLOOKUP(B22,'Discount calculation'!A:A,'Discount calculation'!D:D)} -> 36.494687 | I22: =F22-SUM(G22:H22) -> 1482.4841 | J22: 256.82 | K22: =I22-J22 -> 1225.6641 | L22: 25 | M22: 7.52 | N22: 157.91 | O22: 4.55 | P22: =K22-SUM(L22:O22) -> 1030.6841 | Q22: {=XLOOKUP(B22,'Calculations As per GA Data'!B40:B161,'Calculations As per GA Data'!J40:J161)} -> 1065.6327 | R22: {=XLOOKUP(B22,'Calculations As per GA Data'!B40:B161,'Calculations As per GA Data'!F40:F161)} -> 11 | S22: =P22-Q22 -> -34.948528 | T22: =S22/I22 -> -0.023574302 | U22: 229 | V22: =S22-U22 -> -263.94853 | W22: =V22/I22 -> -0.17804476
A23: Bubbles | B23: Dabble Magic Bubbles POP n PLAY | C23: Bubbles | D23: {=XLOOKUP(B23,'Calculations As per GA Data'!B41:B162,'Calculations As per GA Data'!G41:G162)} -> 20025.399 | E23: 449 | F23: =E23/1.18 -> 380.50847 | G23: 4.75 | H23: {=XLOOKUP(B23,'Discount calculation'!A:A,'Discount calculation'!D:D)} -> 7.3279583 | I23: =F23-SUM(G23:H23) -> 368.43052 | J23: 64.7 | K23: =I23-J23 -> 303.73052 | L23: 5.5 | M23: 7.52 | N23: 100.73208 | O23: 4.55 | P23: =K23-SUM(L23:O23) -> 185.42843 | Q23: {=XLOOKUP(B23,'Calculations As per GA Data'!B41:B162,'Calculations As per GA Data'!J41:J162)} -> 816.85634 | R23: {=XLOOKUP(B23,'Calculations As per GA Data'!B41:B162,'Calculations As per GA Data'!F41:F162)} -> 48 | S23: =P23-Q23 -> -631.4279 | T23: =S23/I23 -> -1.7138317 | U23: 229 | V23: =S23-U23 -> -860.4279 | W23: =V23/I23 -> -2.3353872
A24: FP3+B3+AR | B24: Dabble Starter Pack | Chunkies + Finger Paints + Art Roll | C24: Combo | D24: {=XLOOKUP(B24,'Calculations As per GA Data'!B42:B163,'Calculations As per GA Data'!G42:G163)} -> 12785 | E24: 1897 | F24: =E24/1.18 -> 1607.6271 | G24: 4.75 | H24: {=XLOOKUP(B24,'Discount calculation'!A:A,'Discount calculation'!D:D)} -> 32.313 | I24: =F24-SUM(G24:H24) -> 1570.5641 | J24: 259.46 | K24: =I24-J24 -> 1311.1041 | L24: 20 | M24: 7.52 | N24: 162.85143 | O24: 4.55 | P24: =K24-SUM(L24:O24) -> 1116.1827 | Q24: {=XLOOKUP(B24,'Calculations As per GA Data'!B42:B163,'Calculations As per GA Data'!J42:J163)} -> 844.56352 | R24: {=XLOOKUP(B24,'Calculations As per GA Data'!B42:B163,'Calculations As per GA Data'!F42:F163)} -> 7 | S24: =P24-Q24 -> 271.61917 | T24: =S24/I24 -> 0.1729437 | U24: 229 | V24: =S24-U24 -> 42.61917 | W24: =V24/I24 -> 0.027136218
A25: Preschool kit | B25: Preschool Art and Craft Kit | C25: Preschool kit | D25: {=XLOOKUP(B25,'Calculations As per GA Data'!B43:B164,'Calculations As per GA Data'!G43:G164)} -> 35911.001 | E25: 599 | F25: =E25/1.18 -> 507.62712 | G25: 4.75 | H25: {=XLOOKUP(B25,'Discount calculation'!A:A,'Discount calculation'!D:D)} -> 10.207814 | I25: =F25-SUM(G25:H25) -> 492.6693 | J25: 151.28 | K25: =I25-J25 -> 341.3893 | L25: 12.5 | M25: 7.52 | N25: 121.94607 | O25: 4.55 | P25: =K25-SUM(L25:O25) -> 194.87324 | Q25: {=XLOOKUP(B25,'Calculations As per GA Data'!B43:B164,'Calculations As per GA Data'!J43:J164)} -> 537.50015 | R25: {=XLOOKUP(B25,'Calculations As per GA Data'!B43:B164,'Calculations As per GA Data'!F43:F164)} -> 61 | S25: =P25-Q25 -> -342.62691 | T25: =S25/I25 -> -0.69545008 | U25: 229 | V25: =S25-U25 -> -571.62691 | W25: =V25/I25 -> -1.1602649
A26: SJ+SFP+CB | B26: My First Dabble Swinginâ€™ Jungle Adventure + Mini Starter Fun Pack + Chubby Brushes Combo | C26: Combo | D26: {=XLOOKUP(B26,'Calculations As per GA Data'!B44:B165,'Calculations As per GA Data'!G44:G165)} -> 31366 | E26: 1547 | F26: =E26/1.18 -> 1311.0169 | G26: 4.75 | H26: {=XLOOKUP(B26,'Discount calculation'!A:A,'Discount calculation'!D:D)} -> 28.966465 | I26: =F26-SUM(G26:H26) -> 1277.3005 | J26: 210.73 | K26: =I26-J26 -> 1066.5705 | L26: 20 | M26: 7.52 | N26: 133.70952 | O26: 4.55 | P26: =K26-SUM(L26:O26) -> 900.79096 | Q26: {=XLOOKUP(B26,'Calculations As per GA Data'!B44:B165,'Calculations As per GA Data'!J44:J165)} -> 677.91593 | R26: {=XLOOKUP(B26,'Calculations As per GA Data'!B44:B165,'Calculations As per GA Data'!F44:F165)} -> 21 | S26: =P26-Q26 -> 222.87503 | T26: =S26/I26 -> 0.17448912 | U26: 229 | V26: =S26-U26 -> -6.1249681 | W26: =V26/I26 -> -0.0047952445
A27: B8 | B27: Dabble Playart Crayons | C27: B8 | D27: {=XLOOKUP(B27,'Calculations As per GA Data'!B45:B166,'Calculations As per GA Data'!G45:G166)} -> 23018 | E27: 449 | F27: =E27/1.18 -> 380.50847 | G27: 4.75 | H27: {=XLOOKUP(B27,'Discount calculation'!A:A,'Discount calculation'!D:D)} -> 4.967751 | I27: =F27-SUM(G27:H27) -> 370.79072 | J27: 60.89 | K27: =I27-J27 -> 309.90072 | L27: 5 | M27: 7.52 | N27: 101.03519 | O27: 4.55 | P27: =K27-SUM(L27:O27) -> 191.79553 | Q27: {=XLOOKUP(B27,'Calculations As per GA Data'!B45:B166,'Calculations As per GA Data'!J45:J166)} -> 446.9242 | R27: {=XLOOKUP(B27,'Calculations As per GA Data'!B45:B166,'Calculations As per GA Data'!F45:F166)} -> 52 | S27: =P27-Q27 -> -255.12867 | T27: =S27/I27 -> -0.68806647 | U27: 229 | V27: =S27-U27 -> -484.12867 | W27: =V27/I27 -> -1.3056655
A28: SR | B28: Dabble Sensory Rice Play Kit | C28: SR | D28: {=XLOOKUP(B28,'Calculations As per GA Data'!B46:B167,'Calculations As per GA Data'!G46:G167)} -> 19372 | E28: 699 | F28: =E28/1.18 -> 592.37288 | G28: 4.75 | H28: {=XLOOKUP(B28,'Discount calculation'!A:A,'Discount calculation'!D:D)} -> 8.6020134 | I28: =F28-SUM(G28:H28) -> 579.02087 | J28: 84.27 | K28: =I28-J28 -> 494.75087 | L28: 12.5 | M28: 7.52 | N28: 122.50536 | O28: 4.55 | P28: =K28-SUM(L28:O28) -> 347.67551 | Q28: {=XLOOKUP(B28,'Calculations As per GA Data'!B46:B167,'Calculations As per GA Data'!J46:J167)} -> 1292.3278 | R28: {=XLOOKUP(B28,'Calculations As per GA Data'!B46:B167,'Calculations As per GA Data'!F46:F167)} -> 28 | S28: =P28-Q28 -> -944.65229 | T28: =S28/I28 -> -1.631465 | U28: 229 | V28: =S28-U28 -> -1173.6523 | W28: =V28/I28 -> -2.0269603
A29: Stamp kit | B29: My First Shape Explorer Stamp Kit | C29: Stamp kit | D29: {=XLOOKUP(B29,'Calculations As per GA Data'!B47:B168,'Calculations As per GA Data'!G47:G168)} -> 36963 | E29: 999 | F29: =E29/1.18 -> 846.61017 | G29: 4.75 | H29: {=XLOOKUP(B29,'Discount calculation'!A:A,'Discount calculation'!D:D)} -> 15.105808 | I29: =F29-SUM(G29:H29) -> 826.75436 | J29: 276.02 | K29: =I29-J29 -> 550.73436 | L29: 12.5 | M29: 7.52 | N29: 138.26514 | O29: 4.55 | P29: =K29-SUM(L29:O29) -> 387.89923 | Q29: {=XLOOKUP(B29,'Calculations As per GA Data'!B47:B168,'Calculations As per GA Data'!J47:J168)} -> 366.39731 | R29: {=XLOOKUP(B29,'Calculations As per GA Data'!B47:B168,'Calculations As per GA Data'!F47:F168)} -> 37 | S29: =P29-Q29 -> 21.501912 | T29: =S29/I29 -> 0.026007618 | U29: 229 | V29: =S29-U29 -> -207.49809 | W29: =V29/I29 -> -0.25097913
A30: SR+Playdough | B30: Sensory Discovery Kit | Dabble Sensory Rice + Sensory Play Dough | C30: Combo | D30: {=XLOOKUP(B30,'Calculations As per GA Data'!B48:B169,'Calculations As per GA Data'!G48:G169)} -> 30792 | E30: 1598 | F30: =E30/1.18 -> 1354.2373 | G30: 4.75 | H30: {=XLOOKUP(B30,'Discount calculation'!A:A,'Discount calculation'!D:D)} -> 25.319091 | I30: =F30-SUM(G30:H30) -> 1324.1682 | J30: 208.76 | K30: =I30-J30 -> 1115.4082 | L30: 25 | M30: 7.52 | N30: 157.418 | O30: 4.55 | P30: =K30-SUM(L30:O30) -> 920.9202 | Q30: {=XLOOKUP(B30,'Calculations As per GA Data'!B48:B169,'Calculations As per GA Data'!J48:J169)} -> 823.93481 | R30: {=XLOOKUP(B30,'Calculations As per GA Data'!B48:B169,'Calculations As per GA Data'!F48:F169)} -> 20 | S30: =P30-Q30 -> 96.985384 | T30: =S30/I30 -> 0.073242496 | U30: 229 | V30: =S30-U30 -> -132.01462 | W30: =V30/I30 -> -0.099696259
A31: FP3+JB | B31: Toddler's First Painting Set | Finger Paints + Jumbo Brushes | C31: Combo | D31: {=XLOOKUP(B31,'Calculations As per GA Data'!B49:B170,'Calculations As per GA Data'!G49:G170)} -> 13325 | E31: 1148 | F31: =E31/1.18 -> 972.88136 | G31: 4.75 | H31: {=XLOOKUP(B31,'Discount calculation'!A:A,'Discount calculation'!D:D)} -> 16.005472 | I31: =F31-SUM(G31:H31) -> 952.12588 | J31: 137.96 | K31: =I31-J31 -> 814.16588 | L31: 11.5 | M31: 7.52 | N31: 112.79417 | O31: 4.55 | P31: =K31-SUM(L31:O31) -> 677.80172 | Q31: {=XLOOKUP(B31,'Calculations As per GA Data'!B49:B170,'Calculations As per GA Data'!J49:J170)} -> 863.57429 | R31: {=XLOOKUP(B31,'Calculations As per GA Data'!B49:B170,'Calculations As per GA Data'!F49:F170)} -> 12 | S31: =P31-Q31 -> -185.77257 | T31: =S31/I31 -> -0.19511346 | U31: 229 | V31: =S31-U31 -> -414.77257 | W31: =V31/I31 -> -0.43562787
A32: Mini SPD | B32: Dabble DIY Sensory Playdough Kit | C32: Mini SPD | D32: {=XLOOKUP(B32,'Calculations As per GA Data'!B50:B171,'Calculations As per GA Data'!G50:G171)} -> 18643 | E32: 599 | F32: =E32/1.18 -> 507.62712 | G32: 4.75 | H32: {=XLOOKUP(B32,'Discount calculation'!A:A,'Discount calculation'!D:D)} -> 6.1700658 | I32: =F32-SUM(G32:H32) -> 496.70705 | J32: 56.8 | K32: =I32-J32 -> 439.90705 | L32: 8.5 | M32: 7.52 | N32: 135.315 | O32: 4.55 | P32: =K32-SUM(L32:O32) -> 284.02205 | Q32: {=XLOOKUP(B32,'Calculations As per GA Data'!B50:B171,'Calculations As per GA Data'!J50:J171)} -> 1014.3042 | R32: {=XLOOKUP(B32,'Calculations As per GA Data'!B50:B171,'Calculations As per GA Data'!F50:F171)} -> 34 | S32: =P32-Q32 -> -730.28217 | T32: =S32/I32 -> -1.4702472 | U32: 229 | V32: =S32-U32 -> -959.28217 | W32: =V32/I32 -> -1.9312836
... A40: Canvas | B40: Dabble Canvas Art Board | C40: Canvas | D40: {=XLOOKUP(B40,'Calculations As per GA Data'!B58:B179,'Calculations As per GA Data'!G58:G179)} -> 6080.0002 | E40: 190 | F40: =E40/1.18 -> 161.01695 | G40: 4.75 | H40: {=XLOOKUP(B40,'Discount calculation'!A:A,'Discount calculation'!D:D)} -> 2.1130556 | I40: =F40-SUM(G40:H40) -> 154.15389 | J40: 38.6 | K40: =I40-J40 -> 115.55389 | L40: 8.5 | M40: 7.52 | N40: 109.51286 | O40: 4.55 | P40: =K40-SUM(L40:O40) -> -14.528964 | Q40: {=XLOOKUP(B40,'Calculations As per GA Data'!B58:B179,'Calculations As per GA Data'!J58:J179)} -> 193.18177 | R40: {=XLOOKUP(B40,'Calculations As per GA Data'!B58:B179,'Calculations As per GA Data'!F58:F179)} -> 35 | S40: =P40-Q40 -> -207.71073 | T40: =S40/I40 -> -1.3474245 | U40: 229 | V40: =S40-U40 -> -436.71073 | W40: =V40/I40 -> -2.832953
A41: MPD+AR+JB | B41: Magic Paint Dust + Jumbo Brush Combo Kit + PlayArt Roll â€“ Babyâ€™s First Painting Kit | C41: Combo | D41: {=XLOOKUP(B41,'Calculations As per GA Data'!B59:B180,'Calculations As per GA Data'!G59:G180)} -> 1992 | E41: 2097 | F41: =E41/1.18 -> 1777.1186 | G41: 4.75 | H41: {=XLOOKUP(B41,'Discount calculation'!A:A,'Discount calculation'!D:D)} -> 40.518 | I41: =F41-SUM(G41:H41) -> 1731.8506 | J41: 338.44 | K41: =I41-J41 -> 1393.4106 | L41: 26 | M41: 7.52 | N41: NA | O41: 4.55 | P41: =K41-SUM(L41:O41) -> 1355.3406 | Q41: {=XLOOKUP(B41,'Calculations As per GA Data'!B59:B180,'Calculations As per GA Data'!J59:J180)} -> 10838.565 | R41: {=XLOOKUP(B41,'Calculations As per GA Data'!B59:B180,'Calculations As per GA Data'!F59:F180)} -> 1 | S41: =P41-Q41 -> -9483.2245 | T41: =S41/I41 -> -5.475775 | U41: 229 | V41: =S41-U41 -> -9712.2245 | W41: =V41/I41 -> -5.6080035
A42: DP | B42: Dabble Baby's First Big Colouring Pages | C42: DP | D42: {=XLOOKUP(B42,'Calculations As per GA Data'!B60:B181,'Calculations As per GA Data'!G60:G181)} -> 32903 | E42: 399 | F42: =E42/1.18 -> 338.13559 | G42: 4.75 | H42: {=XLOOKUP(B42,'Discount calculation'!A:A,'Discount calculation'!D:D)} -> 13.496923 | I42: =F42-SUM(G42:H42) -> 319.88867 | J42: 54 | K42: =I42-J42 -> 265.88867 | L42: 8.5 | M42: 7.52 | N42: 145.63595 | O42: 4.55 | P42: =K42-SUM(L42:O42) -> 99.682724 | Q42: {=XLOOKUP(B42,'Calculations As per GA Data'!B60:B181,'Calculations As per GA Data'!J60:J181)} -> 543.62709 | R42: {=XLOOKUP(B42,'Calculations As per GA Data'!B60:B181,'Calculations As per GA Data'!F60:F181)} -> 37 | S42: =P42-Q42 -> -443.94437 | T42: =S42/I42 -> -1.387809 | U42: 229 | V42: =S42-U42 -> -672.94437 | W42: =V42/I42 -> -2.103683
A43: SJ | B43: My First Dabble Swinginâ€™ Jungle Adventure | Reusable Story Card Set | C43: SJ | D43: {=XLOOKUP(B43,'Calculations As per GA Data'!B61:B182,'Calculations As per GA Data'!G61:G182)} -> 10479 | E43: 499 | F43: =E43/1.18 -> 422.88136 | G43: 4.75 | H43: {=XLOOKUP(B43,'Discount calculation'!A:A,'Discount calculation'!D:D)} -> 8.1027273 | I43: =F43-SUM(G43:H43) -> 410.02863 | J43: 45 | K43: =I43-J43 -> 365.02863 | L43: 8.5 | M43: 7.52 | N43: 104.07571 | O43: 4.55 | P43: =K43-SUM(L43:O43) -> 240.38291 | Q43: {=XLOOKUP(B43,'Calculations As per GA Data'!B61:B182,'Calculations As per GA Data'!J61:J182)} -> 959.4371 | R43: {=XLOOKUP(B43,'Calculations As per GA Data'!B61:B182,'Calculations As per GA Data'!F61:F182)} -> 21 | S43: =P43-Q43 -> -719.05419 | T43: =S43/I43 -> -1.7536683 | U43: 229 | V43: =S43-U43 -> -948.05419 | W43: =V43/I43 -> -2.3121658
A44: DP+B8 | B44: Dabble Reusable Colouring Pages + Crayons Combo Kit | C44: Combo | D44: {=XLOOKUP(B44,'Calculations As per GA Data'!B62:B183,'Calculations As per GA Data'!G62:G183)} -> 7341 | E44: 848 | F44: =E44/1.18 -> 718.64407 | G44: 4.75 | H44: {=XLOOKUP(B44,'Discount calculation'!A:A,'Discount calculation'!D:D)} -> 11.2465 | I44: =F44-SUM(G44:H44) -> 702.64757 | J44: 114.89 | K44: =I44-J44 -> 587.75757 | L44: 13.5 | M44: 7.52 | N44: 157.08889 | O44: 4.55 | P44: =K44-SUM(L44:O44) -> 405.09868 | Q44: {=XLOOKUP(B44,'Calculations As per GA Data'!B62:B183,'Calculations As per GA Data'!J62:J183)} -> 755.03763 | R44: {=XLOOKUP(B44,'Calculations As per GA Data'!B62:B183,'Calculations As per GA Data'!F62:F183)} -> 9 | S44: =P44-Q44 -> -349.93895 | T44: =S44/I44 -> -0.49802912 | U44: 229 | V44: =S44-U44 -> -578.93895 | W44: =V44/I44 -> -0.82393931
A45: FP3+AR | B45: Multi Sensory Painting Set | C45: Combo | D45: {=XLOOKUP(B45,'Calculations As per GA Data'!B63:B184,'Calculations As per GA Data'!G63:G184)} -> 2605 | E45: 1348 | F45: =E45/1.18 -> 1142.3729 | G45: 4.75 | H45: {=XLOOKUP(B45,'Discount calculation'!A:A,'Discount calculation'!D:D)} -> 9.0481818 | I45: =F45-SUM(G45:H45) -> 1128.5747 | J45: 193.96 | K45: =I45-J45 -> 934.6147 | L45: 15 | M45: 7.52 | N45: 433.3 | O45: 4.55 | P45: =K45-SUM(L45:O45) -> 474.2447 | Q45: {=XLOOKUP(B45,'Calculations As per GA Data'!B63:B184,'Calculations As per GA Data'!J63:J184)} -> 1494.9745 | R45: {=XLOOKUP(B45,'Calculations As per GA Data'!B63:B184,'Calculations As per GA Data'!F63:F184)} -> 2 | S45: =P45-Q45 -> -1020.7298 | T45: =S45/I45 -> -0.90444151 | U45: 229 | V45: =S45-U45 -> -1249.7298 | W45: =V45/I45 -> -1.1073523
A46: CB | B46: Dabble Chubby Brushes | C46: CB | D46: {=XLOOKUP(B46,'Calculations As per GA Data'!B64:B185,'Calculations As per GA Data'!G64:G185)} -> 7984 | E46: 449 | F46: =E46/1.18 -> 380.50847 | G46: 4.75 | H46: {=XLOOKUP(B46,'Discount calculation'!A:A,'Discount calculation'!D:D)} -> 7.5284694 | I46: =F46-SUM(G46:H46) -> 368.23001 | J46: 76.4 | K46: =I46-J46 -> 291.83001 | L46: 5 | M46: 7.52 | N46: 96.685 | O46: 4.55 | P46: =K46-SUM(L46:O46) -> 178.07501 | Q46: {=XLOOKUP(B46,'Calculations As per GA Data'!B64:B185,'Calculations As per GA Data'!J64:J185)} -> 641.31009 | R46: {=XLOOKUP(B46,'Calculations As per GA Data'!B64:B185,'Calculations As per GA Data'!F64:F185)} -> 16 | S46: =P46-Q46 -> -463.23508 | T46: =S46/I46 -> -1.2580047 | U46: 229 | V46: =S46-U46 -> -692.23508 | W46: =V46/I46 -> -1.8798986
A47: DP+SFP | B47: Dabble Reusable Colouring Pages + Mini Finger Paints Combo Kit | C47: Combo | D47: {=XLOOKUP(B47,'Calculations As per GA Data'!B65:B186,'Calculations As per GA Data'!G65:G186)} -> 3823 | E47: 998 | F47: =E47/1.18 -> 845.76271 | G47: 4.75 | H47: {=XLOOKUP(B47,'Discount calculation'!A:A,'Discount calculation'!D:D)} -> 12.627778 | I47: =F47-SUM(G47:H47) -> 828.38493 | J47: 143.33 | K47: =I47-J47 -> 685.05493 | L47: 15 | M47: 7.52 | N47: 210.6925 | O47: 4.55 | P47: =K47-SUM(L47:O47) -> 447.29243 | Q47: {=XLOOKUP(B47,'Calculations As per GA Data'!B65:B186,'Calculations As per GA Data'!J65:J186)} -> 934.35907 | R47: {=XLOOKUP(B47,'Calculations As per GA Data'!B65:B186,'Calculations As per GA Data'!F65:F186)} -> 4 | S47: =P47-Q47 -> -487.06663 | T47: =S47/I47 -> -0.58797138 | U47: 229 | V47: =S47-U47 -> -716.06663 | W47: =V47/I47 -> -0.86441291
A48: Magic Dough | B48: Dabble Magic Dough Lab â€” Colour Mixing STEAM Kit | C48: Magic Dough | D48: {=XLOOKUP(B48,'Calculations As per GA Data'!B66:B187,'Calculations As per GA Data'!G66:G187)} -> 5519.9999 | E48: 599 | F48: =E48/1.18 -> 507.62712 | G48: 4.75 | H48: {=XLOOKUP(B48,'Discount calculation'!A:A,'Discount calculation'!D:D)} -> 6.2028947 | I48: =F48-SUM(G48:H48) -> 496.67422 | J48: 38.5 | K48: =I48-J48 -> 458.17422 | L48: 8.5 | M48: 7.52 | N48: 133.052 | O48: 4.55 | P48: =K48-SUM(L48:O48) -> 304.55222 | Q48: {=XLOOKUP(B48,'Calculations As per GA Data'!B66:B187,'Calculations As per GA Data'!J66:J187)} -> 1902.6948 | R48: {=XLOOKUP(B48,'Calculations As per GA Data'!B66:B187,'Calculations As per GA Data'!F66:F187)} -> 10 | S48: =P48-Q48 -> -1598.1426 | T48: =S48/I48 -> -3.2176878 | U48: 229 | V48: =S48-U48 -> -1827.1426 | W48: =V48/I48 -> -3.6787546
A49: Puzzle Kit | B49: My First Dabble Puzzle Colouring Set - Emotions, Shapes & Colours | C49: Puzzle Kit | D49: {=XLOOKUP(B49,'Calculations As per GA Data'!B67:B188,'Calculations As per GA Data'!G67:G188)} -> 6433.0001 | E49: 999 | F49: =E49/1.18 -> 846.61017 | G49: 4.75 | H49: {=XLOOKUP(B49,'Discount calculation'!A:A,'Discount calculation'!D:D)} -> 13.530714 | I49: =F49-SUM(G49:H49) -> 828.32946 | J49: 217.35 | K49: =I49-J49 -> 610.97946 | L49: 12.5 | M49: 7.52 | N49: 128.31714 | O49: 4.55 | P49: =K49-SUM(L49:O49) -> 458.09231 | Q49: {=XLOOKUP(B49,'Calculations As per GA Data'!B67:B188,'Calculations As per GA Data'!J67:J188)} -> 1703.6885 | R49: {=XLOOKUP(B49,'Calculations As per GA Data'!B67:B188,'Calculations As per GA Data'!F67:F188)} -> 7 | S49: =P49-Q49 -> -1245.5962 | T49: =S49/I49 -> -1.5037449 | U49: 229 | V49: =S49-U49 -> -1474.5962 | W49: =V49/I49 -> -1.7802049
A50: Dino Kit | B50: Dabble DINOSAUR STENCIL ART & CRAFT Kit | C50: Dino Kit | D50: {=XLOOKUP(B50,'Calculations As per GA Data'!B68:B189,'Calculations As per GA Data'!G68:G189)} -> 10552 | E50: 399 | F50: =E50/1.18 -> 338.13559 | G50: 4.75 | H50: {=XLOOKUP(B50,'Discount calculation'!A:A,'Discount calculation'!D:D)} -> 16.094881 | I50: =F50-SUM(G50:H50) -> 317.29071 | J50: 80.85 | K50: =I50-J50 -> 236.44071 | L50: 8.5 | M50: 7.52 | N50: NA | O50: 4.55 | P50: =K50-SUM(L50:O50) -> 215.87071 | Q50: {=XLOOKUP(B50,'Calculations As per GA Data'!B68:B189,'Calculations As per GA Data'!J68:J189)} -> 1790.147 | R50: {=XLOOKUP(B50,'Calculations As per GA Data'!B68:B189,'Calculations As per GA Data'!F68:F189)} -> 16 | S50: =P50-Q50 -> -1574.2763 | T50: =S50/I50 -> -4.9616212 | U50: 229 | V50: =S50-U50 -> -1803.2763 | W50: =V50/I50 -> -5.6833568
A51: A1 Kit | B51: All In One Paint Kit | C51: A1 Kit | D51: {=XLOOKUP(B51,'Calculations As per GA Data'!B69:B190,'Calculations As per GA Data'!G69:G190)} -> 8620.0002 | E51: 499 | F51: =E51/1.18 -> 422.88136 | G51: 4.75 | H51: {=XLOOKUP(B51,'Discount calculation'!A:A,'Discount calculation'!D:D)} -> 5.7874194 | I51: =F51-SUM(G51:H51) -> 412.34394 | J51: 96.95 | K51: =I51-J51 -> 315.39394 | L51: 12.5 | M51: 7.52 | N51: 119.85056 | O51: 4.55 | P51: =K51-SUM(L51:O51) -> 170.97338 | Q51: {=XLOOKUP(B51,'Calculations As per GA Data'!B69:B190,'Calculations As per GA Data'!J69:J190)} -> 590.81695 | R51: {=XLOOKUP(B51,'Calculations As per GA Data'!B69:B190,'Calculations As per GA Data'!F69:F190)} -> 18 | S51: =P51-Q51 -> -419.84356 | T51: =S51/I51 -> -1.0181878 | U51: 229 | V51: =S51-U51 -> -648.84356 | W51: =V51/I51 -> -1.5735494
A52: FP8+CB+Apron | B52: Dabble Finger Painting Super Pack | C52: Combo | D52: {=XLOOKUP(B52,'Calculations As per GA Data'!B70:B191,'Calculations As per GA Data'!G70:G191)} -> 2104 | E52: 2147 | F52: =E52/1.18 -> 1819.4915 | G52: 4.75 | H52: {=XLOOKUP(B52,'Discount calculation'!A:A,'Discount calculation'!D:D)} -> 33.415714 | I52: =F52-SUM(G52:H52) -> 1781.3258 | J52: 409.6 | K52: =I52-J52 -> 1371.7258 | L52: 19.5 | M52: 7.52 | N52: 270.01 | O52: 4.55 | P52: =K52-SUM(L52:O52) -> 1070.1458 | Q52: {=XLOOKUP(B52,'Calculations As per GA Data'!B70:B191,'Calculations As per GA Data'!J70:J191)} -> 3397.6693 | R52: {=XLOOKUP(B52,'Calculations As per GA Data'!B70:B191,'Calculations As per GA Data'!F70:F191)} -> 1 | S52: =P52-Q52 -> -2327.5235 | T52: =S52/I52 -> -1.3066243 | U52: 229 | V52: =S52-U52 -> -2556.5235 | W52: =V52/I52 -> -1.4351802
...

Sheet Calculations As per GA Data
C2: April | D2: May | E2: June
B3: Shipping Charges | C3: 1,54,407 | D3: 99613 | E3: 1,42,649 | F3: =SUM(C3:E3) -> 99613
B4: Shipping Collection | C4: 8869 | D4: 13524 | E4: 25774 | F4: =SUM(C4:E4) -> 48167 | G4: =F3-F4 -> 51446 | H4: =G4/$C$14 -> 10.475667
B5: Cancellations/returns | C5: 8283 | D5: 3966 | E5: 11097 | F5: =SUM(C5:E5) -> 23346 | H5: =F5/$C$14 -> 4.753818
B6: Discounts | C6: 117671 | D6: 151369 | E6: 151614 | F6: =SUM(C6:E6) -> 420654 | H6: =F6/$C$14 -> 85.655467
B7: Razor pay Deductions | C7: 10612 | D7: 14239 | E7: 12100 | F7: =SUM(C7:E7) -> 36951 | H7: =F7/$C$14 -> 7.5241295
B8: COD Costs | C8: 10073 | D8: 5605 | E8: 6697 | F8: =SUM(C8:E8) -> 22375 | H8: =F8/$C$14 -> 4.5560986
B9: OH Costs | C9: 234 | D9: 191 | E9: 263 | F9: =SUM(C9:E9) -> 688
B10: Google+meta | C10: 352262 | D10: 610707 | E10: 561939 | F10: =SUM(C10:E10) -> 1524908
B11: Bik | C11: 30000 | D11: 15000 | E11: 0 | F11: =SUM(C11:E11) -> 45000
B12: Total Marketing Cost | F12: =SUM(F3:F11) -> 2221702
B13: Cost Per Session | C13: =F12/SUM(D21:D141) -> 33.976693 | H13: =F12/C14 -> 452.393
B14: Total Units Sold In the Last 3 Months | C14: =SUM(F21:F135) -> 4911
B15: Total Sessions | C15: =SUM(D21:D141) -> 65389
B20: Item name | C20: Product | D20: Sessions | E20: Cost Spent | F20: Units sold | G20: Revenue | H20: Items viewed | I20: Items added to cart | J20: Marketing Cost | K20: Item name | L20: Product | M20: CONV
B21: Magic Paint Dust – Baby’s First Painting Kit | C21: =IFERROR(VLOOKUP(B21,K:L,2,0),"NA") -> magic paint dust | D21: {=XLOOKUP(B21,'Google analytics'!A:A,'Google analytics'!F:F)} -> 7147 | E21: =D21*$C$13 -> 242831.43 | F21: {=XLOOKUP(B21,'Data Analytics rawData'!A:A,'Data Analytics rawData'!D:D)} -> 221 | G21: {=XLOOKUP(B21,'Data Analytics rawData'!A:A,'Data Analytics rawData'!E:E)} -> 192044 | H21: {=XLOOKUP(B21,'Data Analytics rawData'!A:A,'Data Analytics rawData'!B:B)} -> 7870 | I21: {=XLOOKUP(B21,'Data Analytics rawData'!A:A,'Data Analytics rawData'!C:C)} -> 781 | J21: =E21/F21 -> 1098.7847 | K21: dabble Sensory Playdough | L21: Playdough | M21: =F21/D21 -> 0.030922065
B22: dabble Sensory Playdough | C22: =IFERROR(VLOOKUP(B22,K:L,2,0),"NA") -> Playdough | D22: {=XLOOKUP(B22,'Google analytics'!A:A,'Google analytics'!F:F)} -> 6541 | E22: =D22*$C$13 -> 222241.55 | F22: {=XLOOKUP(B22,'Data Analytics rawData'!A:A,'Data Analytics rawData'!D:D)} -> 214 | G22: {=XLOOKUP(B22,'Data Analytics rawData'!A:A,'Data Analytics rawData'!E:E)} -> 190336 | H22: {=XLOOKUP(B22,'Data Analytics rawData'!A:A,'Data Analytics rawData'!B:B)} -> 7039 | I22: {=XLOOKUP(B22,'Data Analytics rawData'!A:A,'Data Analytics rawData'!C:C)} -> 761 | J22: =E22/F22 -> 1038.5119 | K22: Magic Paint Dust – Baby’s First Painting Kit | L22: magic paint dust | M22: =F22/D22 -> 0.03271671
B23: Dabble Finger Painting Fun Pack | C23: =IFERROR(VLOOKUP(B23,K:L,2,0),"NA") -> FP8+CB | D23: {=XLOOKUP(B23,'Google analytics'!A:A,'Google analytics'!F:F)} -> 2341 | E23: =D23*$C$13 -> 79539.439 | F23: {=XLOOKUP(B23,'Data Analytics rawData'!A:A,'Data Analytics rawData'!D:D)} -> 122 | G23: {=XLOOKUP(B23,'Data Analytics rawData'!A:A,'Data Analytics rawData'!E:E)} -> 157681 | H23: {=XLOOKUP(B23,'Data Analytics rawData'!A:A,'Data Analytics rawData'!B:B)} -> 2509 | I23: {=XLOOKUP(B23,'Data Analytics rawData'!A:A,'Data Analytics rawData'!C:C)} -> 408 | J23: =E23/F23 -> 651.96262 | K23: Dabble Playart Chunkies | L23: B3 | M23: =F23/D23 -> 0.052114481
B24: Babyâ€™s first handprint and footprint kit | C24: Canvas Kit | D24: {=XLOOKUP(B24,'Google analytics'!A:A,'Google analytics'!F:F)} -> 5252 | E24: =D24*$C$13 -> 178445.59 | F24: {=XLOOKUP(B24,'Data Analytics rawData'!A:A,'Data Analytics rawData'!D:D)} -> 160 | G24: {=XLOOKUP(B24,'Data Analytics rawData'!A:A,'Data Analytics rawData'!E:E)} -> 113540 | H24: {=XLOOKUP(B24,'Data Analytics rawData'!A:A,'Data Analytics rawData'!B:B)} -> 5707 | I24: {=XLOOKUP(B24,'Data Analytics rawData'!A:A,'Data Analytics rawData'!C:C)} -> 623 | J24: =E24/F24 -> 1115.285 | K24: Dabble Finger Painting Fun Pack | L24: FP8+CB | M24: =F24/D24 -> 0.030464585
B25: Mini Starter Finger Painting Fun Pack | C25: =IFERROR(VLOOKUP(B25,K:L,2,0),"NA") -> SFP | D25: {=XLOOKUP(B25,'Google analytics'!A:A,'Google analytics'!F:F)} -> 2316 | E25: =D25*$C$13 -> 78690.022 | F25: {=XLOOKUP(B25,'Data Analytics rawData'!A:A,'Data Analytics rawData'!D:D)} -> 171 | G25: {=XLOOKUP(B25,'Data Analytics rawData'!A:A,'Data Analytics rawData'!E:E)} -> 101319 | H25: {=XLOOKUP(B25,'Data Analytics rawData'!A:A,'Data Analytics rawData'!B:B)} -> 2356 | I25: {=XLOOKUP(B25,'Data Analytics rawData'!A:A,'Data Analytics rawData'!C:C)} -> 636 | J25: =E25/F25 -> 460.17557 | K25: Baby’s Starter Painting + Jumbo Brush Combo Kit | L25: SFP+JB | M25: =F25/D25 -> 0.073834197
B26: Babyâ€™s Starter Painting + Jumbo Brush Combo Kit | C26: SFP+JB | D26: {=XLOOKUP(B26,'Google analytics'!A:A,'Google analytics'!F:F)} -> 1055 | E26: =D26*$C$13 -> 35845.411 | F26: {=XLOOKUP(B26,'Data Analytics rawData'!A:A,'Data Analytics rawData'!D:D)} -> 75 | G26: {=XLOOKUP(B26,'Data Analytics rawData'!A:A,'Data Analytics rawData'!E:E)} -> 79281 | H26: {=XLOOKUP(B26,'Data Analytics rawData'!A:A,'Data Analytics rawData'!B:B)} -> 1094 | I26: {=XLOOKUP(B26,'Data Analytics rawData'!A:A,'Data Analytics rawData'!C:C)} -> 221 | J26: =E26/F26 -> 477.93882 | K26: Mini Starter Finger Painting Fun Pack | L26: SFP | M26: =F26/D26 -> 0.071090047
B27: Dabble Playart Chunkies | C27: =IFERROR(VLOOKUP(B27,K:L,2,0),"NA") -> B3 | D27: {=XLOOKUP(B27,'Google analytics'!A:A,'Google analytics'!F:F)} -> 3472 | E27: =D27*$C$13 -> 117967.08 | F27: {=XLOOKUP(B27,'Data Analytics rawData'!A:A,'Data Analytics rawData'!D:D)} -> 129 | G27: {=XLOOKUP(B27,'Data Analytics rawData'!A:A,'Data Analytics rawData'!E:E)} -> 70820.999 | H27: {=XLOOKUP(B27,'Data Analytics rawData'!A:A,'Data Analytics rawData'!B:B)} -> 3746 | I27: {=XLOOKUP(B27,'Data Analytics rawData'!A:A,'Data Analytics rawData'!C:C)} -> 458 | J27: =E27/F27 -> 914.47348 | K27: Magic Paint Dust + Jumbo Brush Combo Kit – Baby’s First Painting Kit | L27: magic paint dust+jb | M27: =F27/D27 -> 0.037154378
B28: Little Artist Combo Kit | C28: =IFERROR(VLOOKUP(B28,K:L,2,0),"NA") -> FP8, B8, CB | D28: {=XLOOKUP(B28,'Google analytics'!A:A,'Google analytics'!F:F)} -> 1113 | E28: =D28*$C$13 -> 37816.06 | F28: {=XLOOKUP(B28,'Data Analytics rawData'!A:A,'Data Analytics rawData'!D:D)} -> 47 | G28: {=XLOOKUP(B28,'Data Analytics rawData'!A:A,'Data Analytics rawData'!E:E)} -> 81477 | H28: {=XLOOKUP(B28,'Data Analytics rawData'!A:A,'Data Analytics rawData'!B:B)} -> 1235 | I28: {=XLOOKUP(B28,'Data Analytics rawData'!A:A,'Data Analytics rawData'!C:C)} -> 158 | J28: =E28/F28 -> 804.59701 | K28: Little Artist Combo Kit | L28: FP8, B8, CB | M28: =F28/D28 -> 0.042228212
B29: Dabble Starter Painting + Chubby Brush Combo Kit | C29: =IFERROR(VLOOKUP(B29,K:L,2,0),"NA") -> SFP+CB | D29: {=XLOOKUP(B29,'Google analytics'!A:A,'Google analytics'!F:F)} -> 1333 | E29: =D29*$C$13 -> 45290.932 | F29: {=XLOOKUP(B29,'Data Analytics rawData'!A:A,'Data Analytics rawData'!D:D)} -> 90 | G29: {=XLOOKUP(B29,'Data Analytics rawData'!A:A,'Data Analytics rawData'!E:E)} -> 90842 | H29: {=XLOOKUP(B29,'Data Analytics rawData'!A:A,'Data Analytics rawData'!B:B)} -> 1383 | I29: {=XLOOKUP(B29,'Data Analytics rawData'!A:A,'Data Analytics rawData'!C:C)} -> 279 | J29: =E29/F29 -> 503.23258 | K29: Dabble Starter Painting + Chubby Brush Combo Kit | L29: SFP+CB | M29: =F29/D29 -> 0.067516879
B30: Dabble Finger Paints For Toddlers | C30: =IFERROR(VLOOKUP(B30,K:L,2,0),"NA") -> FP3 | D30: {=XLOOKUP(B30,'Google analytics'!A:A,'Google analytics'!F:F)} -> 1422 | E30: =D30*$C$13 -> 48314.858 | F30: {=XLOOKUP(B30,'Data Analytics rawData'!A:A,'Data Analytics rawData'!D:D)} -> 101 | G30: {=XLOOKUP(B30,'Data Analytics rawData'!A:A,'Data Analytics rawData'!E:E)} -> 63589 | H30: {=XLOOKUP(B30,'Data Analytics rawData'!A:A,'Data Analytics rawData'!B:B)} -> 1426 | I30: {=XLOOKUP(B30,'Data Analytics rawData'!A:A,'Data Analytics rawData'!C:C)} -> 350 | J30: =E30/F30 -> 478.36493 | K30: My Dabble ABC Trace & Colour Kit | Multi-Sensory Alphabet Learning for Kids | L30: ABC Kit | M30: =F30/D30 -> 0.071026723
B31: Dabble Art Roll | C31: =IFERROR(VLOOKUP(B31,K:L,2,0),"NA") -> AR | D31: {=XLOOKUP(B31,'Google analytics'!A:A,'Google analytics'!F:F)} -> 718 | E31: =D31*$C$13 -> 24395.266 | F31: {=XLOOKUP(B31,'Data Analytics rawData'!A:A,'Data Analytics rawData'!D:D)} -> 72 | G31: {=XLOOKUP(B31,'Data Analytics rawData'!A:A,'Data Analytics rawData'!E:E)} -> 50328 | H31: {=XLOOKUP(B31,'Data Analytics rawData'!A:A,'Data Analytics rawData'!B:B)} -> 596 | I31: {=XLOOKUP(B31,'Data Analytics rawData'!A:A,'Data Analytics rawData'!C:C)} -> 235 | J31: =E31/F31 -> 338.82314 | K31: Dabble Art Roll | L31: AR | M31: =F31/D31 -> 0.10027855
B32: Magic Paint Dust + Jumbo Brush Combo Kit â€“ Babyâ€™s First Painting Kit | C32: magic paint dust+jb | D32: {=XLOOKUP(B32,'Google analytics'!A:A,'Google analytics'!F:F)} -> 967 | E32: =D32*$C$13 -> 32855.462 | F32: {=XLOOKUP(B32,'Data Analytics rawData'!A:A,'Data Analytics rawData'!D:D)} -> 34 | G32: {=XLOOKUP(B32,'Data Analytics rawData'!A:A,'Data Analytics rawData'!E:E)} -> 45782 | H32: {=XLOOKUP(B32,'Data Analytics rawData'!A:A,'Data Analytics rawData'!B:B)} -> 1002 | I32: {=XLOOKUP(B32,'Data Analytics rawData'!A:A,'Data Analytics rawData'!C:C)} -> 110 | J32: =E32/F32 -> 966.33713 | K32: My First Dabble Swingin’ Jungle Adventure + Crayons Combo | L32: SJ+B8 | M32: =F32/D32 -> 0.03516029
B33: My First Dabble Swinginâ€™ Jungle Adventure + Crayons Combo | C33: SJ+B8 | D33: {=XLOOKUP(B33,'Google analytics'!A:A,'Google analytics'!F:F)} -> 808 | E33: =D33*$C$13 -> 27453.168 | F33: {=XLOOKUP(B33,'Data Analytics rawData'!A:A,'Data Analytics rawData'!D:D)} -> 29 | G33: {=XLOOKUP(B33,'Data Analytics rawData'!A:A,'Data Analytics rawData'!E:E)} -> 26411 | H33: {=XLOOKUP(B33,'Data Analytics rawData'!A:A,'Data Analytics rawData'!B:B)} -> 881 | I33: {=XLOOKUP(B33,'Data Analytics rawData'!A:A,'Data Analytics rawData'!C:C)} -> 129 | J33: =E33/F33 -> 946.66097 | K33: Magic Paint Dust + PlayArt Roll – Baby’s First Painting Kit | L33: MPD+AR | M33: =F33/D33 -> 0.035891089
B34: Masterpiece Set | C34: =IFERROR(VLOOKUP(B34,K:L,2,0),"NA") -> FP8+AR+CB | D34: {=XLOOKUP(B34,'Google analytics'!A:A,'Google analytics'!F:F)} -> 935 | E34: =D34*$C$13 -> 31768.208 | F34: {=XLOOKUP(B34,'Data Analytics rawData'!A:A,'Data Analytics rawData'!D:D)} -> 41 | G34: {=XLOOKUP(B34,'Data Analytics rawData'!A:A,'Data Analytics rawData'!E:E)} -> 80419 | H34: {=XLOOKUP(B34,'Data Analytics rawData'!A:A,'Data Analytics rawData'!B:B)} -> 1018 | I34: {=XLOOKUP(B34,'Data Analytics rawData'!A:A,'Data Analytics rawData'!C:C)} -> 156 | J34: =E34/F34 -> 774.83435 | K34: Baby's First Art Set | L34: B3+AR | M34: =F34/D34 -> 0.043850267
B35: Magic Paint Dust + PlayArt Roll â€“ Babyâ€™s First Painting Kit | C35: MPD+AR | D35: {=XLOOKUP(B35,'Google analytics'!A:A,'Google analytics'!F:F)} -> 729 | E35: =D35*$C$13 -> 24769.009 | F35: {=XLOOKUP(B35,'Data Analytics rawData'!A:A,'Data Analytics rawData'!D:D)} -> 25 | G35: {=XLOOKUP(B35,'Data Analytics rawData'!A:A,'Data Analytics rawData'!E:E)} -> 38622 | H35: {=XLOOKUP(B35,'Data Analytics rawData'!A:A,'Data Analytics rawData'!B:B)} -> 750 | I35: {=XLOOKUP(B35,'Data Analytics rawData'!A:A,'Data Analytics rawData'!C:C)} -> 73 | J35: =E35/F35 -> 990.76038 | K35: Dabble Painting Art Apron | L35: Apron | M35: =F35/D35 -> 0.034293553
B36: Baby's First Art Set | C36: =IFERROR(VLOOKUP(B36,K:L,2,0),"NA") -> B3+AR | D36: {=XLOOKUP(B36,'Google analytics'!A:A,'Google analytics'!F:F)} -> 549 | E36: =D36*$C$13 -> 18653.205 | F36: {=XLOOKUP(B36,'Data Analytics rawData'!A:A,'Data Analytics rawData'!D:D)} -> 12 | G36: {=XLOOKUP(B36,'Data Analytics rawData'!A:A,'Data Analytics rawData'!E:E)} -> 15345 | H36: {=XLOOKUP(B36,'Data Analytics rawData'!A:A,'Data Analytics rawData'!B:B)} -> 590 | I36: {=XLOOKUP(B36,'Data Analytics rawData'!A:A,'Data Analytics rawData'!C:C)} -> 56 | J36: =E36/F36 -> 1554.4337 | K36: Dabble Finger Paints For Toddlers | L36: FP3 | M36: =F36/D36 -> 0.021857924
B37: Dabble Reusable Colouring Pages Kit | C37: =IFERROR(VLOOKUP(B37,K:L,2,0),"NA") -> DP | D37: {=XLOOKUP(B37,'Google analytics'!A:A,'Google analytics'!F:F)} -> 659 | E37: =D37*$C$13 -> 22390.641 | F37: {=XLOOKUP(B37,'Data Analytics rawData'!A:A,'Data Analytics rawData'!D:D)} -> 67 | G37: {=XLOOKUP(B37,'Data Analytics rawData'!A:A,'Data Analytics rawData'!E:E)} -> 24159.85 | H37: {=XLOOKUP(B37,'Data Analytics rawData'!A:A,'Data Analytics rawData'!B:B)} -> 599 | I37: {=XLOOKUP(B37,'Data Analytics rawData'!A:A,'Data Analytics rawData'!C:C)} -> 115 | J37: =E37/F37 -> 334.18867 | K37: Dabble Reusable Colouring Pages Kit | L37: DP | M37: =F37/D37 -> 0.1016692
B38: Dabble Painting Art Apron | C38: =IFERROR(VLOOKUP(B38,K:L,2,0),"NA") -> Apron | D38: {=XLOOKUP(B38,'Google analytics'!A:A,'Google analytics'!F:F)} -> 475 | E38: =D38*$C$13 -> 16138.929 | F38: {=XLOOKUP(B38,'Data Analytics rawData'!A:A,'Data Analytics rawData'!D:D)} -> 50 | G38: {=XLOOKUP(B38,'Data Analytics rawData'!A:A,'Data Analytics rawData'!E:E)} -> 38751.5 | H38: {=XLOOKUP(B38,'Data Analytics rawData'!A:A,'Data Analytics rawData'!B:B)} -> 381 | I38: {=XLOOKUP(B38,'Data Analytics rawData'!A:A,'Data Analytics rawData'!C:C)} -> 131 | J38: =E38/F38 -> 322.77859 | K38: Masterpiece Set | L38: FP8+AR+CB | M38: =F38/D38 -> 0.10526316
B39: My Dabble ABC Trace & Colour Kit | Multi-Sensory Alphabet Learning for Kids | C39: =IFERROR(VLOOKUP(B39,K:L,2,0),"NA") -> ABC Kit | D39: {=XLOOKUP(B39,'Google analytics'!A:A,'Google analytics'!F:F)} -> 2473 | E39: =D39*$C$13 -> 84024.363 | F39: {=XLOOKUP(B39,'Data Analytics rawData'!A:A,'Data Analytics rawData'!D:D)} -> 98 | G39: {=XLOOKUP(B39,'Data Analytics rawData'!A:A,'Data Analytics rawData'!E:E)} -> 58561.999 | H39: {=XLOOKUP(B39,'Data Analytics rawData'!A:A,'Data Analytics rawData'!B:B)} -> 2650 | I39: {=XLOOKUP(B39,'Data Analytics rawData'!A:A,'Data Analytics rawData'!C:C)} -> 330 | J39: =E39/F39 -> 857.39146 | K39: Dabble Playart Finger Paints | L39: FP8 | M39: =F39/D39 -> 0.039627982
B40: Dabble Playart Finger Paints | C40: =IFERROR(VLOOKUP(B40,K:L,2,0),"NA") -> FP8 | D40: {=XLOOKUP(B40,'Google analytics'!A:A,'Google analytics'!F:F)} -> 814 | E40: =D40*$C$13 -> 27657.028 | F40: {=XLOOKUP(B40,'Data Analytics rawData'!A:A,'Data Analytics rawData'!D:D)} -> 60 | G40: {=XLOOKUP(B40,'Data Analytics rawData'!A:A,'Data Analytics rawData'!E:E)} -> 53295 | H40: {=XLOOKUP(B40,'Data Analytics rawData'!A:A,'Data Analytics rawData'!B:B)} -> 853 | I40: {=XLOOKUP(B40,'Data Analytics rawData'!A:A,'Data Analytics rawData'!C:C)} -> 200 | J40: =E40/F40 -> 460.95047 | K40: My First Dabble Swingin’ Jungle Adventure + Mini Starter Fun Pack + Chubby Brushes Combo | L40: SJ+SFP+CB | M40: =F40/D40 -> 0.073710074
B41: Imagination Spark Kit | Dabble Sensory Play Dough + Magic Paint Dust | C41: =IFERROR(VLOOKUP(B41,K:L,2,0),"NA") -> Playdough+MPD | D41: {=XLOOKUP(B41,'Google analytics'!A:A,'Google analytics'!F:F)} -> 345 | E41: =D41*$C$13 -> 11721.959 | F41: {=XLOOKUP(B41,'Data Analytics rawData'!A:A,'Data Analytics rawData'!D:D)} -> 11 | G41: {=XLOOKUP(B41,'Data Analytics rawData'!A:A,'Data Analytics rawData'!E:E)} -> 19004 | H41: {=XLOOKUP(B41,'Data Analytics rawData'!A:A,'Data Analytics rawData'!B:B)} -> 366 | I41: {=XLOOKUP(B41,'Data Analytics rawData'!A:A,'Data Analytics rawData'!C:C)} -> 33 | J41: =E41/F41 -> 1065.6327 | K41: Dabble Christmas Crayons | L41: CC8 | M41: =F41/D41 -> 0.031884058
B42: Dabble Magic Bubbles POP n PLAY | C42: =IFERROR(VLOOKUP(B42,K:L,2,0),"NA") -> Bubbles | D42: {=XLOOKUP(B42,'Google analytics'!A:A,'Google analytics'!F:F)} -> 1154 | E42: =D42*$C$13 -> 39209.104 | F42: {=XLOOKUP(B42,'Data Analytics rawData'!A:A,'Data Analytics rawData'!D:D)} -> 48 | G42: {=XLOOKUP(B42,'Data Analytics rawData'!A:A,'Data Analytics rawData'!E:E)} -> 20025.399 | H42: {=XLOOKUP(B42,'Data Analytics rawData'!A:A,'Data Analytics rawData'!B:B)} -> 1154 | I42: {=XLOOKUP(B42,'Data Analytics rawData'!A:A,'Data Analytics rawData'!C:C)} -> 63 | J42: =E42/F42 -> 816.85634 | K42: Imagination Spark Kit | Dabble Sensory Play Dough + Magic Paint Dust | L42: Playdough+MPD | M42: =F42/D42 -> 0.041594454
B43: Dabble Starter Pack | Chunkies + Finger Paints + Art Roll | C43: =IFERROR(VLOOKUP(B43,K:L,2,0),"NA") -> FP3+B3+AR | D43: {=XLOOKUP(B43,'Google analytics'!A:A,'Google analytics'!F:F)} -> 174 | E43: =D43*$C$13 -> 5911.9446 | F43: {=XLOOKUP(B43,'Data Analytics rawData'!A:A,'Data Analytics rawData'!D:D)} -> 7 | G43: {=XLOOKUP(B43,'Data Analytics rawData'!A:A,'Data Analytics rawData'!E:E)} -> 12785 | H43: {=XLOOKUP(B43,'Data Analytics rawData'!A:A,'Data Analytics rawData'!B:B)} -> 191 | I43: {=XLOOKUP(B43,'Data Analytics rawData'!A:A,'Data Analytics rawData'!C:C)} -> 28 | J43: =E43/F43 -> 844.56352 | K43: Dabble Starter Pack | Chunkies + Finger Paints + Art Roll | L43: FP3+B3+AR | M43: =F43/D43 -> 0.040229885
B44: Preschool Art and Craft Kit | C44: =IFERROR(VLOOKUP(B44,K:L,2,0),"NA") -> Preschool kit | D44: {=XLOOKUP(B44,'Google analytics'!A:A,'Google analytics'!F:F)} -> 965 | E44: =D44*$C$13 -> 32787.509 | F44: {=XLOOKUP(B44,'Data Analytics rawData'!A:A,'Data Analytics rawData'!D:D)} -> 61 | G44: {=XLOOKUP(B44,'Data Analytics rawData'!A:A,'Data Analytics rawData'!E:E)} -> 35911.001 | H44: {=XLOOKUP(B44,'Data Analytics rawData'!A:A,'Data Analytics rawData'!B:B)} -> 1004 | I44: {=XLOOKUP(B44,'Data Analytics rawData'!A:A,'Data Analytics rawData'!C:C)} -> 180 | J44: =E44/F44 -> 537.50015 | K44: Dabble Playart Crayons | L44: B8 | M44: =F44/D44 -> 0.063212435
B45: My First Dabble Swinginâ€™ Jungle Adventure + Mini Starter Fun Pack + Chubby Brushes Combo | C45: SJ+SFP+CB | D45: {=XLOOKUP(B45,'Google analytics'!A:A,'Google analytics'!F:F)} -> 419 | E45: =D45*$C$13 -> 14236.235 | F45: {=XLOOKUP(B45,'Data Analytics rawData'!A:A,'Data Analytics rawData'!D:D)} -> 21 | G45: {=XLOOKUP(B45,'Data Analytics rawData'!A:A,'Data Analytics rawData'!E:E)} -> 31366 | H45: {=XLOOKUP(B45,'Data Analytics rawData'!A:A,'Data Analytics rawData'!B:B)} -> 476 | I45: {=XLOOKUP(B45,'Data Analytics rawData'!A:A,'Data Analytics rawData'!C:C)} -> 74 | J45: =E45/F45 -> 677.91593 | K45: Dabble Sensory Rice Play Kit | L45: SR | M45: =F45/D45 -> 0.050119332
...

Sheet Sheet9
A1: Products Name | B1: Apr | C1: May | D1: Jun | E1: Grand Total | G1: Product Name | H1: Apr | I1: May | J1: Jun | K1: Grand Total
A2: All In One Paint Kit | B2: 205.32 | C2: 191.467 | D2: 1231.677 | E2: 1628.464 | G2: dabble Sensory Playdough | H2: ₹15,089.60 | I2: ₹10,922.39 | J2: ₹9,838.09 | K2: ₹35,850.08
A3: All In One Paint Kit + Playart Crayons Combo | C3: 1192.312 | D3: 245.971 | E3: 1438.283 | G3: Magic Paint Dust – Baby’s First Painting Kit | H3: ₹10,277.79 | I3: ₹11,150.20 | J3: ₹11,835.25 | K3: ₹33,263.25
A4: A-Z Alphabet Printable Activity Pack | D4: 0 | E4: 0 | G4: Mini Starter Finger Painting Fun Pack | H4: ₹9,699.69 | I4: ₹11,058.35 | J4: ₹9,345.18 | K4: ₹30,103.23
A5: B8 | C5: 64.747 | D5: 0 | E5: 64.747 | G5: Babyâ€™s first handprint and footprint kit | H5: ₹1,160.67 | I5: ₹16,600.05 | J5: ₹9,654.80 | K5: ₹27,415.51
A6: Baby's First Art Set | B6: 2382.491 | C6: 3027.609 | D6: 2076.104 | E6: 7486.204 | G6: Dabble Finger Painting Fun Pack | H6: ₹7,590.02 | I6: ₹10,377.61 | J6: ₹5,103.18 | K6: ₹23,070.81
A7: Babys first handprint and footprint kit | B7: 2055.465 | C7: 26923.807 | D7: 3563.503 | E7: 32542.775 | G7: Dabble Flip Flap Make Your Own Dinosaur | Travel-Friendly No Mess DIY Activity Set - Dinosaur | H7: ₹5,106.52 | I7: ₹5,870.69 | J7: ₹8,659.37 | K7: ₹19,636.58
A8: Babys Starter Painting + Jumbo Brush Combo Kit | B8: 3138.673 | C8: 6113.258 | D8: 6768.898 | E8: 16020.829 | G8: Dabble Finger Paints For Toddlers | H8: ₹2,899.19 | I8: ₹5,482.37 | J8: ₹5,699.44 | K8: ₹14,081.00
A9: Creative Wonder Set | Dabble Play Art Chunkies + Sensory Play Dough | B9: 309.608 | C9: 1401.615 | D9: 643.171 | E9: 2354.394 | G9: Dabble Starter Painting + Chubby Brush Combo Kit | H9: ₹4,069.51 | I9: ₹5,478.88 | J9: ₹3,274.42 | K9: ₹12,822.82
A10: Dabble 3 In 1 Easy-Clean Fun Pack | C10: 315.768 | D10: 0 | E10: 315.768 | G10: Dabble Playart Chunkies | H10: ₹4,285.90 | I10: ₹3,898.73 | J10: ₹4,264.85 | K10: ₹12,449.49
A11: Dabble Art Roll | B11: 3639.873 | C11: 7650.734 | D11: 5753.636 | E11: 17044.243 | G11: Dabble Playart Finger Paints | H11: ₹2,344.89 | I11: ₹5,837.72 | J11: ₹3,736.06 | K11: ₹11,918.68
A12: Dabble Baby's First Art Set | Learning &amp; Development Friendly Combo Pack | D12: 571.309 | E12: 571.309 | G12: Babyâ€™s Starter Painting + Jumbo Brush Combo Kit | H12: ₹3,946.53 | I12: ₹4,322.09 | J12: ₹3,247.21 | K12: ₹11,515.82
A13: Dabble Baby's First Big Colouring Pages | B13: 729.146 | C13: 1423.032 | D13: 428.824 | E13: 2581.002 | G13: Canvas and Stand | H13: ₹3,327.82 | I13: ₹3,675.98 | J13: ₹3,907.77 | K13: ₹10,911.56
A14: Dabble Canvas Art Board | B14: 1003.083 | C14: 2511.524 | D14: 779.354 | E14: 4293.961 | G14: Dabble Art Roll | H14: ₹3,308.18 | I14: ₹5,768.12 | J14: ₹1,376.94 | K14: ₹10,453.24
A15: Dabble Christmas Crayons | B15: 565.999 | D15: 0 | E15: 565.999 | G15: Masterpiece Set | H15: ₹3,068.91 | I15: ₹5,332.28 | J15: ₹1,490.90 | K15: ₹9,892.09
A16: Dabble Christmas Crayons + Dabble Pages | B16: 156.916 | D16: 0 | E16: 156.916 | G16: My Dabble ABC Trace & Colour Kit | Multi-Sensory Alphabet Learning for Kids - Crayons | H16: ₹2,791.89 | I16: ₹3,721.26 | J16: ₹2,789.84 | K16: ₹9,302.99
A17: Dabble Chubby Brushes | B17: 420.552 | C17: 1765.452 | D17: 1464.979 | E17: 3650.983 | G17: Little Artist Combo Kit | H17: ₹2,039.12 | I17: ₹3,095.68 | J17: ₹2,902.16 | K17: ₹8,036.96
A18: Dabble Chunky Glue | B18: 1111.371 | C18: 249.051 | D18: 1127.962 | E18: 2488.384 | G18: Preschool Art and Craft Kit | H18: ₹1,931.32 | I18: ₹3,548.83 | J18: ₹1,958.56 | K18: ₹7,438.71
A19: Dabble Dessert Party Pretend Playdough Set | D19: 4108.948 | E19: 4108.948 | G19: Dabble Combo Pack | Crayons + Finger Paints + Art Roll | H19: ₹0.00 | I19: ₹6,913.86 | J19: ₹0.00 | K19: ₹6,913.86
A20: Dabble DINOSAUR STENCIL ART & CRAFT Kit - Pack of 1 | B20: 205.32 | D20: 302.127 | E20: 507.447 | G20: Dabble Reusable Colouring Pages Kit | H20: ₹1,632.65 | I20: ₹2,681.18 | J20: ₹2,167.51 | K20: ₹6,481.34
A21: Dabble DINOSAUR STENCIL ART & CRAFT Kit - Pack of 10 | C21: 714.136 | D21: 0 | E21: 714.136 | G21: Magic Paint Dust + PlayArt Roll â€“ Babyâ€™s First Painting Kit | H21: ₹3,170.51 | I21: ₹2,162.78 | J21: ₹929.08 | K21: ₹6,262.37
A22: Dabble DINOSAUR STENCIL ART & CRAFT Kit - Pack of 5 | B22: 363.062 | D22: 647.466 | E22: 1010.528 | G22: Dabble Painting Art Apron | H22: ₹1,286.97 | I22: ₹2,512.16 | J22: ₹1,696.81 | K22: ₹5,495.95
A23: Dabble DIY Sensory Playdough Kit | D23: 4283.671 | E23: 4283.671 | G23: Dabble Baby's First Big Colouring Pages | H23: ₹918.63 | I23: ₹2,069.89 | J23: ₹2,400.00 | K23: ₹5,388.53
A24: Dabble Essentials Pack | D24: 233.215 | E24: 233.215 | G24: Dabble Playart Crayons | H24: ₹1,196.67 | I24: ₹1,744.04 | J24: ₹2,313.13 | K24: ₹5,253.83
A25: Dabble Finger Painting Fun Pack | B25: 6901.333 | C25: 11844.587 | D25: 8362.185 | E25: 27108.105 | G25: My First Shape Explorer Stamp Kit | H25: ₹1,412.67 | I25: ₹2,778.39 | J25: ₹924.76 | K25: ₹5,115.81
A26: Dabble Finger Painting Super Pack | C26: 390.131 | D26: 0 | E26: 390.131 | G26: Magic Paint Dust + Jumbo Brush Combo Kit â€“ Babyâ€™s First Painting Kit | H26: ₹1,286.40 | I26: ₹2,366.33 | J26: ₹1,279.27 | K26: ₹4,932.00
A27: Dabble Finger Paints + Canvas Art Board | C27: 988.059 | D27: 520.51 | E27: 1508.569 | G27: Dabble Magic Bubbles POP n PLAY | H27: ₹972.19 | I27: ₹2,556.05 | J27: ₹1,306.89 | K27: ₹4,835.14
A28: Dabble Finger Paints For Toddlers | B28: 3660.771 | C28: 5752.859 | D28: 5078.156 | E28: 14491.786 | G28: Dabble DIY Sensory Playdough Kit | H28: ₹1,211.45 | I28: ₹1,799.99 | J28: ₹1,589.27 | K28: ₹4,600.71
A29: Dabble Flip Flap Dress-Up Your Own Unicorn & Princesses | Travel-Friendly No Mess DIY Activity Set - Unicorn & Princesses | C29: 86.376 | D29: 0 | E29: 86.376 | G29: My Dabble ABC Trace & Colour Kit | Multi-Sensory Alphabet Learning for Kids - Paints | H29: ₹1,520.97 | I29: ₹1,620.80 | J29: ₹1,016.38 | K29: ₹4,158.15
A30: Dabble Flip Flap Make Your Own Dinosaur | Travel-Friendly No Mess DIY Activity Set - Unicorn & Princesses | B30: 232.726 | D30: 0 | E30: 232.726 | G30: Baby's First Art Set | H30: ₹1,194.77 | I30: ₹1,053.75 | J30: ₹1,897.23 | K30: ₹4,145.75
A31: Dabble Gift Pack | Chunkies + Finger Paints | B31: 766.764 | C31: 1007.011 | D31: 247.918 | E31: 2021.693 | G31: My First Dabble Swinginâ€™ Jungle Adventure + Crayons Combo | H31: ₹1,187.25 | I31: ₹1,191.51 | J31: ₹1,650.67 | K31: ₹4,029.43
A32: Dabble Gift Set | Crayons + Finger Paints | D32: 169.188 | E32: 169.188 | G32: Dabble Canvas Art Board | H32: ₹1,781.27 | I32: ₹1,091.47 | J32: ₹960.21 | K32: ₹3,832.95
A33: Dabble Jumbo Paint Brush Set | B33: 1573.341 | C33: 2179.952 | D33: 1125.165 | E33: 4878.458 | G33: Dabble Sensory Rice Play Kit | H33: ₹1,922.63 | I33: ₹1,006.94 | J33: ₹500.57 | K33: ₹3,430.15
A34: Dabble Magic Bubbles POP n PLAY | B34: 626.58 | C34: 942.725 | D34: 994.291 | E34: 2563.596 | G34: Dabble Jumbo Paint Brush Set | H34: ₹1,473.82 | I34: ₹1,090.16 | J34: ₹615.36 | K34: ₹3,179.34
A35: Dabble Magic Dough Lab Colour Mixing STEAM Kit | D35: 1446.614 | E35: 1446.614 | G35: Sensory Discovery Kit | Dabble Sensory Rice + Sensory Play Dough | H35: ₹1,024.59 | I35: ₹1,577.16 | J35: ₹546.60 | K35: ₹3,148.36
A36: Dabble magic paint dust | C36: 205.32 | D36: 0 | E36: 205.32 | G36: Dabble Finger Paints + Sensory Playdough Combo | H36: ₹348.01 | I36: ₹1,049.61 | J36: ₹1,604.07 | K36: ₹3,001.69
A37: Dabble Painting Art Apron | B37: 1586.642 | C37: 1391.928 | D37: 2688.536 | E37: 5667.106 | G37: My First Dabble Swinginâ€™ Jungle Adventure + Mini Starter Fun Pack + Chubby Brushes Combo | H37: ₹1,067.02 | I37: ₹635.54 | J37: ₹1,105.34 | K37: ₹2,807.90
A38: Dabble Painting set | Finger Paints + Chubby Brushes | C38: 168.433 | D38: 427.419 | E38: 595.852 | G38: Dabble Chunky Glue | H38: ₹1,138.78 | I38: ₹781.68 | J38: ₹448.01 | K38: ₹2,368.47
A39: Dabble Playart Chunkies | B39: 5854.738 | C39: 6385.983 | D39: 4912.862 | E39: 17153.583 | G39: My First Dabble Swinginâ€™ Jungle Adventure | Reusable Story Card Set | H39: ₹292.55 | I39: ₹1,474.64 | J39: ₹418.40 | K39: ₹2,185.59
A40: Dabble Playart Crayons | B40: 1599.455 | C40: 2500.728 | D40: 2149.938 | E40: 6250.121 | G40: All In One Paint Kit | H40: ₹462.28 | I40: ₹1,217.72 | J40: ₹477.32 | K40: ₹2,157.31
...

