Workbook

Sheet Jan-Mar Unit cost Economic
A1: Product Name | B1: Product Name | C1: Category | D1: 3 month revenue | E1: MRP Including GST | F1: MRP without GST | G1: Returns | H1: Discounts | I1: Net Revenue | J1: Cost of Material | K1: Gross margin | L1: Packaging Secondary | M1: Razorpay Deduction | N1: Shipping to Customer | O1: COD Costs | P1: CM 1 | Q1: Marketing Cost | R1: Units sold | S1: CM 2 | T1: CM 2 % | U1: Overheads | V1: EBIDTA | W1: EBIDTA %
A2: magic paint dust | B2: Magic Paint Dust – Baby’s First Painting Kit | C2: Magic paint dust | D2: 449500 | E2: 899 | F2: 762 | G2: 7.7 | H2: 10.6 | I2: 743.5 | J2: 126.3 | K2: 617.2 | L2: 12.5 | M2: 6.31 | N2: 138.62 | O2: 3.2 | P2: 456.6 | Q2: 910.55 | R2: 500 | S2: -453.9 | T2: -0.6105 | U2: 270 | V2: -723.9 | W2: -0.9736
A3: Playdough | B3: dabble Sensory Playdough | C3: Playdough | D3: 266104 | E3: 899 | F3: 762 | G3: 7.7 | H3: 12.6 | I3: 741.5 | J3: 124.49 | K3: 617 | L3: 12.5 | M3: 6.31 | N3: 121.69 | O3: 3.2 | P3: 473.3 | Q3: 1096.97 | R3: 296 | S3: -623.6 | T3: -0.841 | U3: 270 | V3: -893.6 | W3: -1.2051
A4: FP8+CB | B4: Dabble Finger Painting Fun Pack | C4: Combo | D4: 144640 | E4: 1348 | F4: 1142 | G4: 7.7 | H4: 23.9 | I4: 1110.7 | J4: 238.12 | K4: 872.6 | L4: 14.5 | M4: 6.31 | N4: 239.89 | O4: 3.2 | P4: 608.7 | Q4: 686.3 | R4: 113 | S4: -77.6 | T4: -0.0699 | U4: 270 | V4: -347.6 | W4: -0.313
A5: Canvas Kit | B5: Babyâ€™s first handprint and footprint kit | C5: Canvas Kit | D5: 141482 | E5: 649 | F5: 550 | G5: 7.7 | H5: 5.6 | I5: 536.7 | J5: 70.1 | K5: 466.6 | L5: 12.5 | M5: 6.31 | N5: 149.28 | O5: 3.2 | P5: 295.3 | Q5: 799.95 | R5: 218 | S5: -504.7 | T5: -0.9403 | U5: 270 | V5: -774.7 | W5: -1.4434
A6: SFP | B6: Mini Starter Finger Painting Fun Pack | C6: SFP | D6: 136572 | E6: 599 | F6: 508 | G6: 7.7 | H6: 5.6 | I6: 494.3 | J6: 89.33 | K6: 405 | L6: 6.5 | M6: 6.31 | N6: 165.4 | O6: 3.2 | P6: 223.5 | Q6: 426.91 | R6: 228 | S6: -203.4 | T6: -0.4114 | U6: 270 | V6: -473.4 | W6: -0.9577
A7: SFP+JB | B7: Babyâ€™s Starter Painting + Jumbo Brush Combo Kit | C7: Combo | D7: 111601 | E7: 1098 | F7: 931 | G7: 7.7 | H7: 12.8 | I7: 910 | J7: 117.5 | K7: 792.5 | L7: 11.5 | M7: 6.31 | N7: 149.72 | O7: 3.2 | P7: 621.8 | Q7: 459.32 | R7: 107 | S7: 162.5 | T7: 0.1786 | U7: 270 | V7: -107.5 | W7: -0.1181
A8: B3 | B8: Dabble Playart Chunkies | C8: Caryons | D8: 96426 | E8: 549 | F8: 465 | G8: 7.7 | H8: 7.8 | I8: 449.8 | J8: 65.5 | K8: 384.3 | L8: 5 | M8: 6.31 | N8: 104.6 | O8: 3.2 | P8: 265.2 | Q8: 551.1 | R8: 164 | S8: -285.9 | T8: -0.6358 | U8: 270 | V8: -555.9 | W8: -1.2361
A9: FP8, B8, CB | B9: Little Artist Combo Kit | C9: Combo | D9: 69987 | E9: 1797 | F9: 1523 | G9: 7.7 | H9: 39.3 | I9: 1475.9 | J9: 254.99 | K9: 1220.9 | L9: 19.5 | M9: 6.31 | N9: 248.98 | O9: 3.2 | P9: 942.9 | Q9: 1366.32 | R9: 41 | S9: -423.4 | T9: -0.2869 | U9: 270 | V9: -693.4 | W9: -0.4698
A10: SFP+CB | B10: Dabble Starter Painting + Chubby Brush Combo Kit | C10: Combo | D10: 67660 | E10: 1048 | F10: 888 | G10: 7.7 | H10: 13.4 | I10: 867 | J10: 165.73 | K10: 701.3 | L10: 11.5 | M10: 6.31 | N10: 152.47 | O10: 3.2 | P10: 527.8 | Q10: 462.44 | R10: 68 | S10: 65.3 | T10: 0.0754 | U10: 270 | V10: -204.7 | W10: -0.2361
A11: FP3 | B11: Dabble Finger Paints For Toddlers | C11: FP3 | D11: 67496 | E11: 649 | F11: 550 | G11: 7.7 | H11: 7.6 | I11: 534.7 | J11: 62.96 | K11: 471.8 | L11: 6.5 | M11: 6.31 | N11: 139.34 | O11: 3.2 | P11: 316.4 | Q11: 587.5 | R11: 104 | S11: -271.1 | T11: -0.5069 | U11: 270 | V11: -541.1 | W11: -1.0118
A12: AR | B12: Dabble Art Roll | C12: AR | D12: 63609 | E12: 699 | F12: 592 | G12: 7.7 | H12: 11.4 | I12: 573.3 | J12: 131 | K12: 442.3 | L12: 8.5 | M12: 6.31 | N12: 187.3 | O12: 3.2 | P12: 237 | Q12: 336.4 | R12: 91 | S12: -99.4 | T12: -0.1734 | U12: 270 | V12: -369.4 | W12: -0.6444
A13: magic paint dust+jb | B13: Magic Paint Dust + Jumbo Brush Combo Kit â€“ Babyâ€™s First Painting Kit | C13: Combo | D13: 59760 | E13: 1398 | F13: 1185 | G13: 7.7 | H13: 24.8 | I13: 1152.3 | J13: 182 | K13: 970.3 | L13: 17.5 | M13: 6.31 | N13: 176.18 | O13: 3.2 | P13: 767.1 | Q13: 1121.77 | R13: 45 | S13: -354.7 | T13: -0.3078 | U13: 270 | V13: -624.7 | W13: -0.5422
... A58: SFP+CB+Canvas | B58: Dabble Playtime Prep Kit | C58: Combo | D58: 4704 | E58: 1238 | F58: 1049 | G58: 7.7 | H58: 17.5 | I58: 1023.9 | J58: 204.33 | K58: 819.6 | L58: 20 | M58: 6.31 | N58: 39.23 | O58: 3.2 | P58: 750.8 | Q58: 843.41 | R58: 4 | S58: -92.6 | T58: -0.0904 | U58: 270 | V58: -362.6 | W58: -0.3541
A59: Activity Pack | B59: A-Z Alphabet Printable Activity Pack | C59: Activity Pack | D59: 4059 | E59: 99 | F59: 84 | G59: 7.7 | H59: 0.8 | I59: 75.4 | K59: 75.4 | M59: 6.31 | N59: 0 | O59: 3.2 | P59: 65.8 | Q59: 1422.19 | R59: 41 | S59: -1356.4 | T59: -17.9994 | U59: 270 | V59: -1626.4 | W59: -21.5824
A60: Glue | B60: Dabble Chunky Glue | C60: Glue | D60: 3839 | E60: 349 | F60: 296 | G60: 7.7 | H60: 4.9 | I60: 283.1 | J60: 50.42 | K60: 232.7 | L60: 5 | M60: 6.31 | N60: 226.22 | O60: 3.2 | P60: -8 | Q60: 613.39 | R60: 11 | S60: -621.4 | T60: -2.1948 | U60: 270 | V60: -891.4 | W60: -3.1485
A61: SFP+CB+Apron | B61: Dabble Essentials Pack | C61: Combo | D61: 3694 | E61: 1847 | F61: 1565 | G61: 7.7 | H61: 46.7 | I61: 1510.8 | J61: 381.3 | K61: 1129.5 | L61: 16.5 | M61: 6.31 | N61: 116.61 | O61: 3.2 | P61: 986.9 | Q61: 1166.2 | R61: 2 | S61: -179.3 | T61: -0.1187 | U61: 270 | V61: -449.3 | W61: -0.2974
A62: Dino+B8 | B62: Flip Flap Crayon Play Pack Dinosaur Themed | Activity Book with Crayons | | C62: Combo | D62: 3302 | E62: 998 | F62: 846 | G62: 7.7 | H62: 19.1 | I62: 818.9 | J62: 141.74 | K62: 677.2 | L62: 10.5 | M62: 6.31 | N62: 190.1 | O62: 3.2 | P62: 467.1 | Q62: 572.69 | R62: 4 | S62: -105.6 | T62: -0.129 | U62: 270 | V62: -375.6 | W62: -0.4587
A63: SJ+SFP | B63: My First Dabble Swinginâ€™ Jungle Adventure + Mini Starter Fun Pack Combo | C63: Combo | D63: 3129 | E63: 1098 | F63: 931 | G63: 7.7 | H63: 15.1 | I63: 907.7 | J63: 134.33 | K63: 773.4 | L63: 15 | M63: 6.31 | N63: 0 | O63: 3.2 | P63: 748.8 | Q63: 1679.88 | R63: 3 | S63: -931 | T63: -1.0257 | U63: 270 | V63: -1201 | W63: -1.3232
A64: FP3+CB | B64: Dabble Painting set | Finger Paints + Chubby Brushes | C64: Combo | D64: 3129 | E64: 1098 | F64: 931 | G64: 7.7 | H64: 14.3 | I64: 908.5 | J64: 139.36 | K64: 769.1 | L64: 11.5 | M64: 6.31 | N64: 198.62 | O64: 3.2 | P64: 549.5 | Q64: 985.72 | R64: 3 | S64: -436.2 | T64: -0.4802 | U64: 270 | V64: -706.2 | W64: -0.7774
A65: FP3+Glue+AR+B3 | B65: My First Dabble Art Set For Toddlers | C65: Combo | D65: 2246 | E65: 2246 | F65: 1903 | G65: 7.7 | H65: 112.3 | I65: 1783.4 | J65: 309.88 | K65: 1473.5 | L65: 25 | M65: 6.31 | N65: 189.74 | O65: 3.2 | P65: 1249.3 | Q65: 3290.34 | R65: 1 | S65: -2041.1 | T65: -1.1445 | U65: 270 | V65: -2311.1 | W65: -1.2959
A66: CC8+DP | B66: Dabble Christmas Crayons + Dabble Pages | C66: Combo | D66: 1800 | E66: NA | F66: 1048 | G66: 7.7 | H66: 15.3 | I66: 1025 | J66: 135.4 | K66: 889.6 | L66: 13.5 | M66: 6.31 | N66: 78.46 | O66: 3.2 | P66: 788.1 | Q66: 354.02 | R66: 2 | S66: 434.1 | T66: 0.4235 | U66: 270 | V66: 164.1 | W66: 0.1601
A67: SFP+AR+Apron | B67: Dabble Sensory Painting Kit | C67: Combo | D67: 1747 | E67: 1747 | F67: 1481 | G67: 7.7 | H67: 22 | I67: 1450.8 | J67: 435.83 | K67: 1015 | L67: 20 | M67: 6.31 | N67: 605.48 | O67: 3.2 | P67: 380 | Q67: 1707.65 | R67: 1 | S67: -1327.6 | T67: -0.9151 | U67: 270 | V67: -1597.6 | W67: -1.1012
A68: Glue+FP3+B8 | B68: Dabble 3 In 1 Easy-Clean Fun Pack | C68: Combo | D68: 1374 | E68: 1447 | F68: 1226 | G68: 7.7 | H68: 9.7 | I68: 1208.9 | J68: 174.27 | K68: 1034.6 | L68: 16.5 | M68: 6.31 | N68: 315.77 | O68: 3.2 | P68: 692.8 | Q68: 2374.05 | R68: 1 | S68: -1681.2 | T68: -1.3907 | U68: 270 | V68: -1951.2 | W68: -1.6141
A69: Canvas & Stand | B69: Canvas and Stand | C69: Canvas & Stand | D69: 940.8001 | E69: 160 | F69: 136 | G69: 7.7 | H69: 1.4 | I69: 126.5 | K69: 126.5 | M69: 6.31 | N69: 0 | O69: 3.2 | P69: 117 | Q69: 71.4 | R69: 7 | S69: 45.6 | T69: 0.3606 | U69: 270 | V69: -224.4 | W69: -1.7731
A70: FF Unicorn + Dino | B70: Flip Flap Play Pack | Activity Book | | C70: Combo | D70: 845 | E70: 1098 | F70: 931 | G70: 7.7 | H70: 5 | I70: 917.8 | J70: 212 | K70: 705.8 | L70: 11 | M70: 6.31 | N70: 297.08 | O70: 3.2 | P70: 388.2 | Q70: 3790.14 | R70: 1 | S70: -3401.9 | T70: -3.7064 | U70: 270 | V70: -3671.9 | W70: -4.0006
A71: FF Unicorn | B71: Dabble Flip Flap Dress-Up Your Own Unicorn & Princesses | Travel-Friendly No Mess DIY Activity Set | C71: FF Unicorn | D71: 844 | E71: 549 | F71: 465 | G71: 7.7 | H71: 2.8 | I71: 454.7 | J71: 106 | K71: 348.7 | L71: 5.5 | M71: 6.31 | N71: 0 | O71: 3.2 | P71: 333.7 | Q71: 124.95 | R71: 2 | S71: 208.8 | T71: 0.4591 | U71: 270 | V71: -61.2 | W71: -0.1346
A72: Activity Pack | B72: Numbers 1-10 Printable Activity Pack | C72: Activity Pack | D72: 791.9999 | E72: 99 | F72: 84 | G72: 7.7 | H72: 0.7 | I72: 75.5 | K72: 75.5 | M72: 6.31 | N72: 0 | O72: 3.2 | P72: 66 | Q72: 708.05 | R72: 8 | S72: -642.1 | T72: -8.5028 | U72: 270 | V72: -912.1 | W72: -12.0785
A73: DP+Glue | B73: Dabble Reusable Colouring Pages + Glue Combo Kit | C73: Combo | D73: 710 | E73: 748 | F73: 634 | G73: 7.7 | H73: 6.7 | I73: 619.5 | J73: 104.42 | K73: 515.1 | L73: 13.5 | M73: 6.31 | N73: 323.73 | O73: 3.2 | P73: 168.3 | Q73: 2915.5 | R73: 1 | S73: -2747.2 | T73: -4.4344 | U73: 270 | V73: -3017.2 | W73: -4.8703
A74: ABC Crayons | B74: My Dabble ABC Trace & Colour Kit | Multi-Sensory Alphabet Learning for Kids - Crayons | C74: ABC Crayons | D74: 664 | E74: 699 | F74: 592 | G74: 7.7 | H74: =#N/A -> #N/A | I74: =#N/A -> #N/A | J74: 105 | K74: =#N/A -> #N/A | L74: 8.5 | M74: 6.31 | N74: 6583.12 | O74: 3.2 | P74: =#N/A -> #N/A | Q74: 52812.12 | R74: 1 | S74: =#N/A -> #N/A | T74: =#N/A -> #N/A | U74: 270 | V74: =#N/A -> #N/A | W74: =#N/A -> #N/A
A75: FF Dino | B75: Dabble Flip Flap Make Your Own Dinosaur | Travel-Friendly No Mess DIY Activity Set | C75: FF Dino | D75: 549 | E75: 549 | F75: 465 | G75: 7.7 | H75: 10.1 | I75: 447.5 | K75: 447.5 | M75: 6.31 | N75: 0 | O75: 3.2 | P75: 438 | Q75: 708.05 | R75: 1 | S75: -270.1 | T75: -0.6036 | U75: 270 | V75: -540.1 | W75: -1.2069
A76: P&B | B76: Palette & Brush | C76: P&B | D76: 299 | E76: 299 | F76: 253 | G76: 7.7 | H76: 6 | I76: 239.7 | J76: 34 | K76: 205.7 | L76: 4 | M76: 6.31 | N76: 0 | O76: 3.2 | P76: 192.2 | Q76: 833 | R76: 1 | S76: -640.8 | T76: -2.6732 | U76: 270 | V76: -910.8 | W76: -3.7996
A77: NA | B77: Bake dough- (Green) | C77: NA | D77: 0 | E77: NA | F77: NA | G77: 7.7 | H77: =#N/A -> #N/A | I77: =#N/A -> #N/A | K77: =#N/A -> #N/A | M77: 6.31 | N77: 0 | O77: 3.2 | P77: =#N/A -> #N/A | Q77: =#DIV/0! -> #DIV/0! | R77: 0 | S77: =#N/A -> #N/A | T77: =#N/A -> #N/A | U77: 270 | V77: =#N/A -> #N/A | W77: =#N/A -> #N/A
A78: NA | B78: Bakedough-Pizza Blue | C78: NA | D78: 0 | E78: NA | F78: NA | G78: 7.7 | H78: =#N/A -> #N/A | I78: =#N/A -> #N/A | K78: =#N/A -> #N/A | M78: 6.31 | N78: 0 | O78: 3.2 | P78: =#N/A -> #N/A | Q78: =#DIV/0! -> #DIV/0! | R78: 0 | S78: =#N/A -> #N/A | T78: =#N/A -> #N/A | U78: 270 | V78: =#N/A -> #N/A | W78: =#N/A -> #N/A
A79: NA | B79: Bakedough-Pizza Green | C79: NA | D79: 0 | E79: NA | F79: NA | G79: 7.7 | H79: =#N/A -> #N/A | I79: =#N/A -> #N/A | K79: =#N/A -> #N/A | M79: 6.31 | N79: 0 | O79: 3.2 | P79: =#N/A -> #N/A | Q79: =#DIV/0! -> #DIV/0! | R79: 0 | S79: =#N/A -> #N/A | T79: =#N/A -> #N/A | U79: 270 | V79: =#N/A -> #N/A | W79: =#N/A -> #N/A
A80: B8+FP3+AR | B80: Dabble Combo Pack | Crayons + Finger Paints + Art Roll | C80: Combo | D80: 0 | E80: 1797 | F80: 1523 | G80: 7.7 | H80: =#N/A -> #N/A | I80: =#N/A -> #N/A | K80: =#N/A -> #N/A | M80: 6.31 | N80: 0 | O80: 3.2 | P80: =#N/A -> #N/A | Q80: =#DIV/0! -> #DIV/0! | R80: 0 | S80: =#N/A -> #N/A | T80: =#N/A -> #N/A | U80: 270 | V80: =#N/A -> #N/A | W80: =#N/A -> #N/A
A81: Dino Kit | B81: Dabble DINOSAUR STENCIL ART & CRAFT Kit - Pack of 1 | C81: Dino Kit | D81: 0 | E81: 399 | F81: 338 | G81: 7.7 | H81: =#N/A -> #N/A | I81: =#N/A -> #N/A | K81: =#N/A -> #N/A | M81: 6.31 | N81: 0 | O81: 3.2 | P81: =#N/A -> #N/A | Q81: =#DIV/0! -> #DIV/0! | R81: 0 | S81: =#N/A -> #N/A | T81: =#N/A -> #N/A | U81: 270 | V81: =#N/A -> #N/A | W81: =#N/A -> #N/A
A82: Dino Kit | B82: Dabble DINOSAUR STENCIL ART & CRAFT Kit - Pack of 10 | C82: Dino Kit | D82: 0 | E82: 3990 | F82: 3381 | G82: 7.7 | H82: =#N/A -> #N/A | I82: =#N/A -> #N/A | K82: =#N/A -> #N/A | M82: 6.31 | N82: 0 | O82: 3.2 | P82: =#N/A -> #N/A | Q82: =#DIV/0! -> #DIV/0! | R82: 0 | S82: =#N/A -> #N/A | T82: =#N/A -> #N/A | U82: 270 | V82: =#N/A -> #N/A | W82: =#N/A -> #N/A
A83: Dino Kit | B83: Dabble DINOSAUR STENCIL ART & CRAFT Kit - Pack of 5 | C83: Dino Kit | D83: 0 | E83: 1995 | F83: 1691 | G83: 7.7 | H83: =#N/A -> #N/A | I83: =#N/A -> #N/A | K83: =#N/A -> #N/A | M83: 6.31 | N83: 0 | O83: 3.2 | P83: =#N/A -> #N/A | Q83: =#DIV/0! -> #DIV/0! | R83: 0 | S83: =#N/A -> #N/A | T83: =#N/A -> #N/A | U83: 270 | V83: =#N/A -> #N/A | W83: =#N/A -> #N/A
A84: Dino Kit | B84: Dabble DINOSAUR STENCIL ART &amp; CRAFT Kit - Pack of 5 | C84: Dino Kit | D84: 0 | E84: 1995 | F84: 1691 | G84: 7.7 | H84: =#N/A -> #N/A | I84: =#N/A -> #N/A | K84: =#N/A -> #N/A | M84: 6.31 | N84: 0 | O84: 3.2 | P84: =#N/A -> #N/A | Q84: =#DIV/0! -> #DIV/0! | R84: 0 | S84: =#N/A -> #N/A | T84: =#N/A -> #N/A | U84: 270 | V84: =#N/A -> #N/A | W84: =#N/A -> #N/A
...

Sheet April-June Unit Cost Ecomomic
A1: Product Name | B1: Product Name | C1: Category | D1: 3 month revenue | E1: MRP Including GST | F1: MRP without GST | G1: Returns | H1: Discounts | I1: Net Revenue | J1: Cost of Material | K1: Gross margin | L1: Packaging Secondary | M1: Razorpay Deduction | N1: Shipping to Customer | O1: COD Costs | P1: CM 1 | Q1: Marketing Cost | R1: Units sold | S1: CM 2 | T1: CM 2 % | U1: Overheads | V1: EBIDTA | W1: EBIDTA %
A2: magic paint dust | B2: Magic Paint Dust – Baby’s First Painting Kit | C2: Magic paint dust | D2: 192044 | E2: 899 | F2: 762 | G2: 4.8 | H2: 11.1 | I2: 746 | J2: 126.3 | K2: 619.7 | L2: 12.5 | M2: 7.52 | N2: 150.51 | O2: 4.55 | P2: 444.6 | Q2: 1098.78 | R2: 221 | S2: -654.2 | T2: -0.8769 | U2: 229 | V2: -883.2 | W2: -1.1839
A3: Playdough | B3: dabble Sensory Playdough | C3: Playdough | D3: 190336 | E3: 899 | F3: 762 | G3: 4.8 | H3: 11.3 | I3: 745.8 | J3: 124.49 | K3: 621.4 | L3: 12.5 | M3: 7.52 | N3: 167.52 | O3: 4.55 | P3: 429.3 | Q3: 1038.51 | R3: 214 | S3: -609.3 | T3: -0.8169 | U3: 229 | V3: -838.3 | W3: -1.1239
A4: FP8+CB | B4: Dabble Finger Painting Fun Pack | C4: Combo | D4: 157681 | E4: 1348 | F4: 1142 | G4: 4.8 | H4: 17.4 | I4: 1120.3 | J4: 238.12 | K4: 882.1 | L4: 14.5 | M4: 7.52 | N4: 189.11 | O4: 4.55 | P4: 666.5 | Q4: 651.96 | R4: 122 | S4: 14.5 | T4: 0.0129 | U4: 229 | V4: -214.5 | W4: -0.1915
A5: Canvas Kit | B5: Babyâ€™s first handprint and footprint kit | C5: Canvas Kit | D5: 113540 | E5: 649 | F5: 550 | G5: 4.8 | H5: 8.2 | I5: 537.1 | J5: 70.1 | K5: 467 | L5: 12.5 | M5: 7.52 | N5: 171.35 | O5: 4.55 | P5: 271.1 | Q5: 1115.28 | R5: 160 | S5: -844.2 | T5: -1.5719 | U5: 229 | V5: -1073.2 | W5: -1.9983
A6: SFP | B6: Mini Starter Finger Painting Fun Pack | C6: SFP | D6: 101319 | E6: 599 | F6: 508 | G6: 4.8 | H6: 6.5 | I6: 496.4 | J6: 89.33 | K6: 407 | L6: 6.5 | M6: 7.52 | N6: 176.04 | O6: 4.55 | P6: 212.4 | Q6: 460.18 | R6: 171 | S6: -247.8 | T6: -0.4992 | U6: 229 | V6: -476.8 | W6: -0.9605
A7: SFP+JB | B7: Babyâ€™s Starter Painting + Jumbo Brush Combo Kit | C7: Combo | D7: 79281 | E7: 1098 | F7: 931 | G7: 4.8 | H7: 12.2 | I7: 913.5 | J7: 117.5 | K7: 796 | L7: 11.5 | M7: 7.52 | N7: 153.54 | O7: 4.55 | P7: 618.9 | Q7: 477.94 | R7: 75 | S7: 141 | T7: 0.1543 | U7: 229 | V7: -88 | W7: -0.0964
A8: B3 | B8: Dabble Playart Chunkies | C8: Caryons | D8: 70821 | E8: 549 | F8: 465 | G8: 4.8 | H8: 6.1 | I8: 454.4 | J8: 65.5 | K8: 388.9 | L8: 5 | M8: 7.52 | N8: 96.51 | O8: 4.55 | P8: 275.4 | Q8: 914.47 | R8: 129 | S8: -639.1 | T8: -1.4064 | U8: 229 | V8: -868.1 | W8: -1.9103
A9: FP8, B8, CB | B9: Little Artist Combo Kit | C9: Combo | D9: 81477 | E9: 1797 | F9: 1523 | G9: 4.8 | H9: 30.1 | I9: 1488 | J9: 254.99 | K9: 1233 | L9: 19.5 | M9: 7.52 | N9: 171 | O9: 4.55 | P9: 1030.5 | Q9: 804.6 | R9: 47 | S9: 225.9 | T9: 0.1518 | U9: 229 | V9: -3.1 | W9: -0.0021
A10: SFP+CB | B10: Dabble Starter Painting + Chubby Brush Combo Kit | C10: Combo | D10: 90842 | E10: 1048 | F10: 888 | G10: 4.8 | H10: 11.8 | I10: 871.6 | J10: 165.73 | K10: 705.9 | L10: 11.5 | M10: 7.52 | N10: 142.48 | O10: 4.55 | P10: 539.8 | Q10: 503.23 | R10: 90 | S10: 36.6 | T10: 0.042 | U10: 229 | V10: -192.4 | W10: -0.2208
A11: FP3 | B11: Dabble Finger Paints For Toddlers | C11: FP3 | D11: 63589 | E11: 649 | F11: 550 | G11: 4.8 | H11: 9.5 | I11: 535.8 | J11: 62.96 | K11: 472.8 | L11: 6.5 | M11: 7.52 | N11: 139.42 | O11: 4.55 | P11: 314.8 | Q11: 478.36 | R11: 101 | S11: -163.5 | T11: -0.3053 | U11: 229 | V11: -392.5 | W11: -0.7327
A12: AR | B12: Dabble Art Roll | C12: AR | D12: 50328 | E12: 699 | F12: 592 | G12: 4.8 | H12: 9.6 | I12: 578 | J12: 131 | K12: 447 | L12: 8.5 | M12: 7.52 | N12: 145.18 | O12: 4.55 | P12: 281.2 | Q12: 338.82 | R12: 72 | S12: -57.6 | T12: -0.0996 | U12: 229 | V12: -286.6 | W12: -0.4958
A13: magic paint dust+jb | B13: Magic Paint Dust + Jumbo Brush Combo Kit â€“ Babyâ€™s First Painting Kit | C13: Combo | D13: 45782 | E13: 1398 | F13: 1185 | G13: 4.8 | H13: 22.7 | I13: 1157.3 | J13: 182 | K13: 975.3 | L13: 17.5 | M13: 7.52 | N13: 145.06 | O13: 4.55 | P13: 800.7 | Q13: 966.34 | R13: 34 | S13: -165.6 | T13: -0.1431 | U13: 229 | V13: -394.6 | W13: -0.341
... A19: Apron | B19: Dabble Painting Art Apron | C19: Apron | D19: 38751.5 | E19: 799 | F19: 677 | G19: 4.8 | H19: 12.8 | I19: 659.5 | J19: 215.5 | K19: 444 | L19: 5 | M19: 7.52 | N19: 109.92 | O19: 4.55 | P19: 317.1 | Q19: 322.78 | R19: 50 | S19: -5.7 | T19: -0.0087 | U19: 229 | V19: -234.7 | W19: -0.3559
A20: ABC Kit | B20: My Dabble ABC Trace & Colour Kit | Multi-Sensory Alphabet Learning for Kids | C20: ABC Kit | D20: 58562 | E20: 699 | F20: 592 | G20: 4.8 | H20: 7.2 | I20: 580.5 | J20: 105 | K20: 475.5 | L20: 8.5 | M20: 7.52 | N20: NA | O20: 4.55 | P20: 454.9 | Q20: 857.39 | R20: 98 | S20: -402.5 | T20: -0.6934 | U20: 229 | V20: -631.5 | W20: -1.0879
A21: FP8 | B21: Dabble Playart Finger Paints | C21: FP8 | D21: 53295 | E21: 899 | F21: 762 | G21: 4.8 | H21: 11.6 | I21: 745.5 | J21: 117.7 | K21: 627.8 | L21: 9.5 | M21: 7.52 | N21: 198.64 | O21: 4.55 | P21: 407.6 | Q21: 460.95 | R21: 60 | S21: -53.4 | T21: -0.0716 | U21: 229 | V21: -282.4 | W21: -0.3788
A22: Playdough+MPD | B22: Imagination Spark Kit | Dabble Sensory Play Dough + Magic Paint Dust | C22: Combo | D22: 19004 | E22: 1798 | F22: 1524 | G22: 4.8 | H22: 36.5 | I22: 1482.5 | J22: 256.82 | K22: 1225.7 | L22: 25 | M22: 7.52 | N22: 157.91 | O22: 4.55 | P22: 1030.7 | Q22: 1065.63 | R22: 11 | S22: -34.9 | T22: -0.0236 | U22: 229 | V22: -263.9 | W22: -0.178
A23: Bubbles | B23: Dabble Magic Bubbles POP n PLAY | C23: Bubbles | D23: 20025.4 | E23: 449 | F23: 381 | G23: 4.8 | H23: 7.3 | I23: 368.4 | J23: 64.7 | K23: 303.7 | L23: 5.5 | M23: 7.52 | N23: 100.73 | O23: 4.55 | P23: 185.4 | Q23: 816.86 | R23: 48 | S23: -631.4 | T23: -1.7138 | U23: 229 | V23: -860.4 | W23: -2.3354
A24: FP3+B3+AR | B24: Dabble Starter Pack | Chunkies + Finger Paints + Art Roll | C24: Combo | D24: 12785 | E24: 1897 | F24: 1608 | G24: 4.8 | H24: 32.3 | I24: 1570.6 | J24: 259.46 | K24: 1311.1 | L24: 20 | M24: 7.52 | N24: 162.85 | O24: 4.55 | P24: 1116.2 | Q24: 844.56 | R24: 7 | S24: 271.6 | T24: 0.1729 | U24: 229 | V24: 42.6 | W24: 0.0271
A25: Preschool kit | B25: Preschool Art and Craft Kit | C25: Preschool kit | D25: 35911 | E25: 599 | F25: 508 | G25: 4.8 | H25: 10.2 | I25: 492.7 | J25: 151.28 | K25: 341.4 | L25: 12.5 | M25: 7.52 | N25: 121.95 | O25: 4.55 | P25: 194.9 | Q25: 537.5 | R25: 61 | S25: -342.6 | T25: -0.6955 | U25: 229 | V25: -571.6 | W25: -1.1603
A26: SJ+SFP+CB | B26: My First Dabble Swinginâ€™ Jungle Adventure + Mini Starter Fun Pack + Chubby Brushes Combo | C26: Combo | D26: 31366 | E26: 1547 | F26: 1311 | G26: 4.8 | H26: 29 | I26: 1277.3 | J26: 210.73 | K26: 1066.6 | L26: 20 | M26: 7.52 | N26: 133.71 | O26: 4.55 | P26: 900.8 | Q26: 677.92 | R26: 21 | S26: 222.9 | T26: 0.1745 | U26: 229 | V26: -6.1 | W26: -0.0048
A27: B8 | B27: Dabble Playart Crayons | C27: B8 | D27: 23018 | E27: 449 | F27: 381 | G27: 4.8 | H27: 5 | I27: 370.8 | J27: 60.89 | K27: 309.9 | L27: 5 | M27: 7.52 | N27: 101.04 | O27: 4.55 | P27: 191.8 | Q27: 446.92 | R27: 52 | S27: -255.1 | T27: -0.6881 | U27: 229 | V27: -484.1 | W27: -1.3057
A28: SR | B28: Dabble Sensory Rice Play Kit | C28: SR | D28: 19372 | E28: 699 | F28: 592 | G28: 4.8 | H28: 8.6 | I28: 579 | J28: 84.27 | K28: 494.8 | L28: 12.5 | M28: 7.52 | N28: 122.51 | O28: 4.55 | P28: 347.7 | Q28: 1292.33 | R28: 28 | S28: -944.7 | T28: -1.6315 | U28: 229 | V28: -1173.7 | W28: -2.027
A29: Stamp kit | B29: My First Shape Explorer Stamp Kit | C29: Stamp kit | D29: 36963 | E29: 999 | F29: 847 | G29: 4.8 | H29: 15.1 | I29: 826.8 | J29: 276.02 | K29: 550.7 | L29: 12.5 | M29: 7.52 | N29: 138.27 | O29: 4.55 | P29: 387.9 | Q29: 366.4 | R29: 37 | S29: 21.5 | T29: 0.026 | U29: 229 | V29: -207.5 | W29: -0.251
A30: SR+Playdough | B30: Sensory Discovery Kit | Dabble Sensory Rice + Sensory Play Dough | C30: Combo | D30: 30792 | E30: 1598 | F30: 1354 | G30: 4.8 | H30: 25.3 | I30: 1324.2 | J30: 208.76 | K30: 1115.4 | L30: 25 | M30: 7.52 | N30: 157.42 | O30: 4.55 | P30: 920.9 | Q30: 823.93 | R30: 20 | S30: 97 | T30: 0.0732 | U30: 229 | V30: -132 | W30: -0.0997
A31: FP3+JB | B31: Toddler's First Painting Set | Finger Paints + Jumbo Brushes | C31: Combo | D31: 13325 | E31: 1148 | F31: 973 | G31: 4.8 | H31: 16 | I31: 952.1 | J31: 137.96 | K31: 814.2 | L31: 11.5 | M31: 7.52 | N31: 112.79 | O31: 4.55 | P31: 677.8 | Q31: 863.57 | R31: 12 | S31: -185.8 | T31: -0.1951 | U31: 229 | V31: -414.8 | W31: -0.4356
A32: Mini SPD | B32: Dabble DIY Sensory Playdough Kit | C32: Mini SPD | D32: 18643 | E32: 599 | F32: 508 | G32: 4.8 | H32: 6.2 | I32: 496.7 | J32: 56.8 | K32: 439.9 | L32: 8.5 | M32: 7.52 | N32: 135.32 | O32: 4.55 | P32: 284 | Q32: 1014.3 | R32: 34 | S32: -730.3 | T32: -1.4702 | U32: 229 | V32: -959.3 | W32: -1.9313
A33: DP+Playdough | B33: Endless Creations Pack | Dabble Reusable Colouring Pages + Sensory Play Dough | C33: Combo | D33: 7476 | E33: 1298 | F33: 1100 | G33: 4.8 | H33: 24.3 | I33: 1071 | J33: 178.49 | K33: 892.5 | L33: 21 | M33: 7.52 | N33: 104.65 | O33: 4.55 | P33: 754.8 | Q33: 1319.43 | R33: 6 | S33: -564.7 | T33: -0.5272 | U33: 229 | V33: -793.7 | W33: -0.7411
A34: Playdough+AR | B34: Little Makerâ€™s Set | Dabble Sensory Play Dough + Painting Apron | C34: Combo | D34: 17315 | E34: 1648 | F34: 1397 | G34: 4.8 | H34: =#N/A -> #N/A | I34: =#N/A -> #N/A | J34: 255.49 | K34: =#N/A -> #N/A | L34: 17.5 | M34: 7.52 | N34: 151.7 | O34: 4.55 | P34: =#N/A -> #N/A | Q34: 1498.06 | R34: 11 | S34: =#N/A -> #N/A | T34: =#N/A -> #N/A | U34: 229 | V34: =#N/A -> #N/A | W34: =#N/A -> #N/A
A35: B8+AR | B35: Toddlers First Colouring Set | Playart Crayons + Art Roll | C35: Combo | D35: 7279 | E35: 1148 | F35: 973 | G35: 4.8 | H35: 17.1 | I35: 951 | J35: 191.89 | K35: 759.1 | L35: 10 | M35: 7.52 | N35: 193.2 | O35: 4.55 | P35: 543.8 | Q35: 732.93 | R35: 7 | S35: -189.1 | T35: -0.1988 | U35: 229 | V35: -418.1 | W35: -0.4396
A36: JB | B36: Dabble Jumbo Paint Brush Set | C36: JB | D36: 14469 | E36: 499 | F36: 423 | G36: 4.8 | H36: 5.7 | I36: 412.4 | J36: 75 | K36: 337.4 | L36: 5 | M36: 7.52 | N36: 102.56 | O36: 4.55 | P36: 217.8 | Q36: 714.61 | R36: 31 | S36: -496.8 | T36: -1.2048 | U36: 229 | V36: -725.8 | W36: -1.7601
A37: Mini Dessert Party | B37: Dabble Dessert Party Pretend Playdough Set | C37: Mini Dessert Party | D37: 12172 | E37: 599 | F37: 508 | G37: 4.8 | H37: 11.2 | I37: 491.7 | J37: 76.7 | K37: 415 | L37: 8.5 | M37: 7.52 | N37: 84.43 | O37: 4.55 | P37: 310 | Q37: 1718.91 | R37: 22 | S37: -1408.9 | T37: -2.8655 | U37: 229 | V37: -1637.9 | W37: -3.3312
A38: FP3+B3 | B38: Dabble Gift Pack | Chunkies + Finger Paints | C38: Combo | D38: 8038 | E38: 1198 | F38: 1015 | G38: 4.8 | H38: 15.5 | I38: 995 | J38: 128.46 | K38: 866.5 | L38: 11.5 | M38: 7.52 | N38: 89.1 | O38: 4.55 | P38: 753.9 | Q38: 825.15 | R38: 7 | S38: -71.3 | T38: -0.0716 | U38: 229 | V38: -300.3 | W38: -0.3018
A39: B3+Playdough | B39: Creative Wonder Set | Dabble Play Art Chunkies + Sensory Play Dough | C39: Combo | D39: 13926 | E39: 1448 | F39: 1227 | G39: 4.8 | H39: 25.9 | I39: 1196.5 | J39: 189.99 | K39: 1006.5 | L39: 17.5 | M39: 7.52 | N39: 151.05 | O39: 4.55 | P39: 825.9 | Q39: 1002.31 | R39: 10 | S39: -176.5 | T39: -0.1475 | U39: 229 | V39: -405.5 | W39: -0.3389
A40: Canvas | B40: Dabble Canvas Art Board | C40: Canvas | D40: 6080 | E40: 190 | F40: 161 | G40: 4.8 | H40: 2.1 | I40: 154.2 | J40: 38.6 | K40: 115.6 | L40: 8.5 | M40: 7.52 | N40: 109.51 | O40: 4.55 | P40: -14.5 | Q40: 193.18 | R40: 35 | S40: -207.7 | T40: -1.3474 | U40: 229 | V40: -436.7 | W40: -2.833
A41: MPD+AR+JB | B41: Magic Paint Dust + Jumbo Brush Combo Kit + PlayArt Roll â€“ Babyâ€™s First Painting Kit | C41: Combo | D41: 1992 | E41: 2097 | F41: 1777 | G41: 4.8 | H41: 40.5 | I41: 1731.9 | J41: 338.44 | K41: 1393.4 | L41: 26 | M41: 7.52 | N41: NA | O41: 4.55 | P41: 1355.3 | Q41: 10838.57 | R41: 1 | S41: -9483.2 | T41: -5.4758 | U41: 229 | V41: -9712.2 | W41: -5.608
A42: DP | B42: Dabble Baby's First Big Colouring Pages | C42: DP | D42: 32903 | E42: 399 | F42: 338 | G42: 4.8 | H42: 13.5 | I42: 319.9 | J42: 54 | K42: 265.9 | L42: 8.5 | M42: 7.52 | N42: 145.64 | O42: 4.55 | P42: 99.7 | Q42: 543.63 | R42: 37 | S42: -443.9 | T42: -1.3878 | U42: 229 | V42: -672.9 | W42: -2.1037
A43: SJ | B43: My First Dabble Swinginâ€™ Jungle Adventure | Reusable Story Card Set | C43: SJ | D43: 10479 | E43: 499 | F43: 423 | G43: 4.8 | H43: 8.1 | I43: 410 | J43: 45 | K43: 365 | L43: 8.5 | M43: 7.52 | N43: 104.08 | O43: 4.55 | P43: 240.4 | Q43: 959.44 | R43: 21 | S43: -719.1 | T43: -1.7537 | U43: 229 | V43: -948.1 | W43: -2.3122
A44: DP+B8 | B44: Dabble Reusable Colouring Pages + Crayons Combo Kit | C44: Combo | D44: 7341 | E44: 848 | F44: 719 | G44: 4.8 | H44: 11.2 | I44: 702.6 | J44: 114.89 | K44: 587.8 | L44: 13.5 | M44: 7.52 | N44: 157.09 | O44: 4.55 | P44: 405.1 | Q44: 755.04 | R44: 9 | S44: -349.9 | T44: -0.498 | U44: 229 | V44: -578.9 | W44: -0.8239
A45: FP3+AR | B45: Multi Sensory Painting Set | C45: Combo | D45: 2605 | E45: 1348 | F45: 1142 | G45: 4.8 | H45: 9 | I45: 1128.6 | J45: 193.96 | K45: 934.6 | L45: 15 | M45: 7.52 | N45: 433.3 | O45: 4.55 | P45: 474.2 | Q45: 1494.97 | R45: 2 | S45: -1020.7 | T45: -0.9044 | U45: 229 | V45: -1249.7 | W45: -1.1074
...

Sheet Jan-Mar Summary
A1: Jan-Mar Summary — Unit Cost Economics
A3: Average CAC (₹) — fixed input: | D3: 650
A5: Product | B5: MRP (₹) | C5: Units (3mo) | D5: Revenue (₹) | E5: GM/unit (₹) | F5: GM % | G5: Shipping/unit (₹) | H5: Profit/unit after ads+ship (₹) | I5: 3-mo profit (₹)
A6: ='Jan-Mar Unit cost Economic'!B2 -> Magic Paint Dust – Baby’s First Painting Kit | B6: =IF(ISNUMBER('Jan-Mar Unit cost Economic'!E2),'Jan-Mar Unit cost Economic'!E2,"n/a") -> 899 | C6: =IFERROR(N('Jan-Mar Unit cost Economic'!R2),0) -> 500 | D6: =IFERROR(N('Jan-Mar Unit cost Economic'!D2),0) -> 449500 | E6: =ROUND(IFERROR(N('Jan-Mar Unit cost Economic'!K2),0),0) -> 617 | F6: =IFERROR(E6/(D6/C6),0) -> 0.68631813 | G6: =ROUND(IFERROR(N('Jan-Mar Unit cost Economic'!N2),0),0) -> 139 | H6: =ROUND(E6-$D$3-G6,0) -> -172 | I6: =ROUND(H6*C6,0) -> -86000
A7: ='Jan-Mar Unit cost Economic'!B3 -> dabble Sensory Playdough | B7: =IF(ISNUMBER('Jan-Mar Unit cost Economic'!E3),'Jan-Mar Unit cost Economic'!E3,"n/a") -> 899 | C7: =IFERROR(N('Jan-Mar Unit cost Economic'!R3),0) -> 296 | D7: =IFERROR(N('Jan-Mar Unit cost Economic'!D3),0) -> 266104 | E7: =ROUND(IFERROR(N('Jan-Mar Unit cost Economic'!K3),0),0) -> 617 | F7: =IFERROR(E7/(D7/C7),0) -> 0.68631813 | G7: =ROUND(IFERROR(N('Jan-Mar Unit cost Economic'!N3),0),0) -> 122 | H7: =ROUND(E7-$D$3-G7,0) -> -155 | I7: =ROUND(H7*C7,0) -> -45880
A8: ='Jan-Mar Unit cost Economic'!B4 -> Dabble Finger Painting Fun Pack | B8: =IF(ISNUMBER('Jan-Mar Unit cost Economic'!E4),'Jan-Mar Unit cost Economic'!E4,"n/a") -> 1348 | C8: =IFERROR(N('Jan-Mar Unit cost Economic'!R4),0) -> 113 | D8: =IFERROR(N('Jan-Mar Unit cost Economic'!D4),0) -> 144640 | E8: =ROUND(IFERROR(N('Jan-Mar Unit cost Economic'!K4),0),0) -> 873 | F8: =IFERROR(E8/(D8/C8),0) -> 0.68203125 | G8: =ROUND(IFERROR(N('Jan-Mar Unit cost Economic'!N4),0),0) -> 240 | H8: =ROUND(E8-$D$3-G8,0) -> -17 | I8: =ROUND(H8*C8,0) -> -1921
A9: ='Jan-Mar Unit cost Economic'!B5 -> Babyâ€™s first handprint and footprint kit | B9: =IF(ISNUMBER('Jan-Mar Unit cost Economic'!E5),'Jan-Mar Unit cost Economic'!E5,"n/a") -> 649 | C9: =IFERROR(N('Jan-Mar Unit cost Economic'!R5),0) -> 218 | D9: =IFERROR(N('Jan-Mar Unit cost Economic'!D5),0) -> 141482 | E9: =ROUND(IFERROR(N('Jan-Mar Unit cost Economic'!K5),0),0) -> 467 | F9: =IFERROR(E9/(D9/C9),0) -> 0.71956857 | G9: =ROUND(IFERROR(N('Jan-Mar Unit cost Economic'!N5),0),0) -> 149 | H9: =ROUND(E9-$D$3-G9,0) -> -332 | I9: =ROUND(H9*C9,0) -> -72376
A10: ='Jan-Mar Unit cost Economic'!B6 -> Mini Starter Finger Painting Fun Pack | B10: =IF(ISNUMBER('Jan-Mar Unit cost Economic'!E6),'Jan-Mar Unit cost Economic'!E6,"n/a") -> 599 | C10: =IFERROR(N('Jan-Mar Unit cost Economic'!R6),0) -> 228 | D10: =IFERROR(N('Jan-Mar Unit cost Economic'!D6),0) -> 136572 | E10: =ROUND(IFERROR(N('Jan-Mar Unit cost Economic'!K6),0),0) -> 405 | F10: =IFERROR(E10/(D10/C10),0) -> 0.67612688 | G10: =ROUND(IFERROR(N('Jan-Mar Unit cost Economic'!N6),0),0) -> 165 | H10: =ROUND(E10-$D$3-G10,0) -> -410 | I10: =ROUND(H10*C10,0) -> -93480
A11: ='Jan-Mar Unit cost Economic'!B7 -> Babyâ€™s Starter Painting + Jumbo Brush Combo Kit | B11: =IF(ISNUMBER('Jan-Mar Unit cost Economic'!E7),'Jan-Mar Unit cost Economic'!E7,"n/a") -> 1098 | C11: =IFERROR(N('Jan-Mar Unit cost Economic'!R7),0) -> 107 | D11: =IFERROR(N('Jan-Mar Unit cost Economic'!D7),0) -> 111601 | E11: =ROUND(IFERROR(N('Jan-Mar Unit cost Economic'!K7),0),0) -> 793 | F11: =IFERROR(E11/(D11/C11),0) -> 0.76030681 | G11: =ROUND(IFERROR(N('Jan-Mar Unit cost Economic'!N7),0),0) -> 150 | H11: =ROUND(E11-$D$3-G11,0) -> -7 | I11: =ROUND(H11*C11,0) -> -749
A12: ='Jan-Mar Unit cost Economic'!B8 -> Dabble Playart Chunkies | B12: =IF(ISNUMBER('Jan-Mar Unit cost Economic'!E8),'Jan-Mar Unit cost Economic'!E8,"n/a") -> 549 | C12: =IFERROR(N('Jan-Mar Unit cost Economic'!R8),0) -> 164 | D12: =IFERROR(N('Jan-Mar Unit cost Economic'!D8),0) -> 96426 | E12: =ROUND(IFERROR(N('Jan-Mar Unit cost Economic'!K8),0),0) -> 384 | F12: =IFERROR(E12/(D12/C12),0) -> 0.65310186 | G12: =ROUND(IFERROR(N('Jan-Mar Unit cost Economic'!N8),0),0) -> 105 | H12: =ROUND(E12-$D$3-G12,0) -> -371 | I12: =ROUND(H12*C12,0) -> -60844
A13: ='Jan-Mar Unit cost Economic'!B9 -> Little Artist Combo Kit | B13: =IF(ISNUMBER('Jan-Mar Unit cost Economic'!E9),'Jan-Mar Unit cost Economic'!E9,"n/a") -> 1797 | C13: =IFERROR(N('Jan-Mar Unit cost Economic'!R9),0) -> 41 | D13: =IFERROR(N('Jan-Mar Unit cost Economic'!D9),0) -> 69987 | E13: =ROUND(IFERROR(N('Jan-Mar Unit cost Economic'!K9),0),0) -> 1221 | F13: =IFERROR(E13/(D13/C13),0) -> 0.71528998 | G13: =ROUND(IFERROR(N('Jan-Mar Unit cost Economic'!N9),0),0) -> 249 | H13: =ROUND(E13-$D$3-G13,0) -> 322 | I13: =ROUND(H13*C13,0) -> 13202
A14: ='Jan-Mar Unit cost Economic'!B10 -> Dabble Starter Painting + Chubby Brush Combo Kit | B14: =IF(ISNUMBER('Jan-Mar Unit cost Economic'!E10),'Jan-Mar Unit cost Economic'!E10,"n/a") -> 1048 | C14: =IFERROR(N('Jan-Mar Unit cost Economic'!R10),0) -> 68 | D14: =IFERROR(N('Jan-Mar Unit cost Economic'!D10),0) -> 67660 | E14: =ROUND(IFERROR(N('Jan-Mar Unit cost Economic'!K10),0),0) -> 701 | F14: =IFERROR(E14/(D14/C14),0) -> 0.70452261 | G14: =ROUND(IFERROR(N('Jan-Mar Unit cost Economic'!N10),0),0) -> 152 | H14: =ROUND(E14-$D$3-G14,0) -> -101 | I14: =ROUND(H14*C14,0) -> -6868
A15: ='Jan-Mar Unit cost Economic'!B11 -> Dabble Finger Paints For Toddlers | B15: =IF(ISNUMBER('Jan-Mar Unit cost Economic'!E11),'Jan-Mar Unit cost Economic'!E11,"n/a") -> 649 | C15: =IFERROR(N('Jan-Mar Unit cost Economic'!R11),0) -> 104 | D15: =IFERROR(N('Jan-Mar Unit cost Economic'!D11),0) -> 67496 | E15: =ROUND(IFERROR(N('Jan-Mar Unit cost Economic'!K11),0),0) -> 472 | F15: =IFERROR(E15/(D15/C15),0) -> 0.72727273 | G15: =ROUND(IFERROR(N('Jan-Mar Unit cost Economic'!N11),0),0) -> 139 | H15: =ROUND(E15-$D$3-G15,0) -> -317 | I15: =ROUND(H15*C15,0) -> -32968
A16: ='Jan-Mar Unit cost Economic'!B12 -> Dabble Art Roll | B16: =IF(ISNUMBER('Jan-Mar Unit cost Economic'!E12),'Jan-Mar Unit cost Economic'!E12,"n/a") -> 699 | C16: =IFERROR(N('Jan-Mar Unit cost Economic'!R12),0) -> 91 | D16: =IFERROR(N('Jan-Mar Unit cost Economic'!D12),0) -> 63609 | E16: =ROUND(IFERROR(N('Jan-Mar Unit cost Economic'!K12),0),0) -> 442 | F16: =IFERROR(E16/(D16/C16),0) -> 0.6323319 | G16: =ROUND(IFERROR(N('Jan-Mar Unit cost Economic'!N12),0),0) -> 187 | H16: =ROUND(E16-$D$3-G16,0) -> -395 | I16: =ROUND(H16*C16,0) -> -35945
A17: ='Jan-Mar Unit cost Economic'!B13 -> Magic Paint Dust + Jumbo Brush Combo Kit â€“ Babyâ€™s First Painting Kit | B17: =IF(ISNUMBER('Jan-Mar Unit cost Economic'!E13),'Jan-Mar Unit cost Economic'!E13,"n/a") -> 1398 | C17: =IFERROR(N('Jan-Mar Unit cost Economic'!R13),0) -> 45 | D17: =IFERROR(N('Jan-Mar Unit cost Economic'!D13),0) -> 59760 | E17: =ROUND(IFERROR(N('Jan-Mar Unit cost Economic'!K13),0),0) -> 970 | F17: =IFERROR(E17/(D17/C17),0) -> 0.73042169 | G17: =ROUND(IFERROR(N('Jan-Mar Unit cost Economic'!N13),0),0) -> 176 | H17: =ROUND(E17-$D$3-G17,0) -> 144 | I17: =ROUND(H17*C17,0) -> 6480
... A77: ='Jan-Mar Unit cost Economic'!B73 -> Dabble Reusable Colouring Pages + Glue Combo Kit | B77: =IF(ISNUMBER('Jan-Mar Unit cost Economic'!E73),'Jan-Mar Unit cost Economic'!E73,"n/a") -> 748 | C77: =IFERROR(N('Jan-Mar Unit cost Economic'!R73),0) -> 1 | D77: =IFERROR(N('Jan-Mar Unit cost Economic'!D73),0) -> 710 | E77: =ROUND(IFERROR(N('Jan-Mar Unit cost Economic'!K73),0),0) -> 515 | F77: =IFERROR(E77/(D77/C77),0) -> 0.72535211 | G77: =ROUND(IFERROR(N('Jan-Mar Unit cost Economic'!N73),0),0) -> 324 | H77: =ROUND(E77-$D$3-G77,0) -> -459 | I77: =ROUND(H77*C77,0) -> -459
A78: ='Jan-Mar Unit cost Economic'!B75 -> Dabble Flip Flap Make Your Own Dinosaur | Travel-Friendly No Mess DIY Activity Set | B78: =IF(ISNUMBER('Jan-Mar Unit cost Economic'!E75),'Jan-Mar Unit cost Economic'!E75,"n/a") -> 549 | C78: =IFERROR(N('Jan-Mar Unit cost Economic'!R75),0) -> 1 | D78: =IFERROR(N('Jan-Mar Unit cost Economic'!D75),0) -> 549 | E78: =ROUND(IFERROR(N('Jan-Mar Unit cost Economic'!K75),0),0) -> 448 | F78: =IFERROR(E78/(D78/C78),0) -> 0.81602914 | G78: =ROUND(IFERROR(N('Jan-Mar Unit cost Economic'!N75),0),0) -> 0 | H78: =ROUND(E78-$D$3-G78,0) -> -202 | I78: =ROUND(H78*C78,0) -> -202
A79: ='Jan-Mar Unit cost Economic'!B76 -> Palette & Brush | B79: =IF(ISNUMBER('Jan-Mar Unit cost Economic'!E76),'Jan-Mar Unit cost Economic'!E76,"n/a") -> 299 | C79: =IFERROR(N('Jan-Mar Unit cost Economic'!R76),0) -> 1 | D79: =IFERROR(N('Jan-Mar Unit cost Economic'!D76),0) -> 299 | E79: =ROUND(IFERROR(N('Jan-Mar Unit cost Economic'!K76),0),0) -> 206 | F79: =IFERROR(E79/(D79/C79),0) -> 0.68896321 | G79: =ROUND(IFERROR(N('Jan-Mar Unit cost Economic'!N76),0),0) -> 0 | H79: =ROUND(E79-$D$3-G79,0) -> -444 | I79: =ROUND(H79*C79,0) -> -444
A81: GRAND TOTAL | B81: — | C81: =SUM(C6:C79) -> 3206 | D81: =SUM(D6:D79) -> 2614540.5 | E81: =ROUND(IFERROR(SUMPRODUCT(E6:E79,C6:C79)/C81,0),0) -> 564 | F81: =IFERROR(E81/(D81/C81),0) -> 0.69158768 | G81: =ROUND(IFERROR(SUMPRODUCT(G6:G79,C6:C79)/C81,0),0) -> 140 | H81: =ROUND(IFERROR(I81/C81,0),0) -> -226 | I81: =SUM(I6:I79) -> -724822

Sheet Apr-Jun Summary
A1: Apr-Jun Summary — Unit Cost Economics
A3: Average CAC (₹) — fixed input: | D3: 595
A5: Product | B5: MRP (₹) | C5: Units (3mo) | D5: Revenue (₹) | E5: GM/unit (₹) | F5: GM % | G5: Shipping/unit (₹) | H5: Profit/unit after ads+ship (₹) | I5: 3-mo profit (₹)
A6: ='April-June Unit Cost Ecomomic'!B2 -> Magic Paint Dust – Baby’s First Painting Kit | B6: =IF(ISNUMBER('April-June Unit Cost Ecomomic'!E2),'April-June Unit Cost Ecomomic'!E2,"n/a") -> 899 | C6: =IFERROR(N('April-June Unit Cost Ecomomic'!R2),0) -> 221 | D6: =IFERROR(N('April-June Unit Cost Ecomomic'!D2),0) -> 192044 | E6: =ROUND(IFERROR(N('April-June Unit Cost Ecomomic'!K2),0),0) -> 620 | F6: =IFERROR(E6/(D6/C6),0) -> 0.71348233 | G6: =ROUND(IFERROR(N('April-June Unit Cost Ecomomic'!N2),0),0) -> 151 | H6: =ROUND(E6-$D$3-G6,0) -> -126 | I6: =ROUND(H6*C6,0) -> -27846
A7: ='April-June Unit Cost Ecomomic'!B3 -> dabble Sensory Playdough | B7: =IF(ISNUMBER('April-June Unit Cost Ecomomic'!E3),'April-June Unit Cost Ecomomic'!E3,"n/a") -> 899 | C7: =IFERROR(N('April-June Unit Cost Ecomomic'!R3),0) -> 214 | D7: =IFERROR(N('April-June Unit Cost Ecomomic'!D3),0) -> 190336 | E7: =ROUND(IFERROR(N('April-June Unit Cost Ecomomic'!K3),0),0) -> 621 | F7: =IFERROR(E7/(D7/C7),0) -> 0.69820738 | G7: =ROUND(IFERROR(N('April-June Unit Cost Ecomomic'!N3),0),0) -> 168 | H7: =ROUND(E7-$D$3-G7,0) -> -142 | I7: =ROUND(H7*C7,0) -> -30388
A8: ='April-June Unit Cost Ecomomic'!B4 -> Dabble Finger Painting Fun Pack | B8: =IF(ISNUMBER('April-June Unit Cost Ecomomic'!E4),'April-June Unit Cost Ecomomic'!E4,"n/a") -> 1348 | C8: =IFERROR(N('April-June Unit Cost Ecomomic'!R4),0) -> 122 | D8: =IFERROR(N('April-June Unit Cost Ecomomic'!D4),0) -> 157681 | E8: =ROUND(IFERROR(N('April-June Unit Cost Ecomomic'!K4),0),0) -> 882 | F8: =IFERROR(E8/(D8/C8),0) -> 0.68241576 | G8: =ROUND(IFERROR(N('April-June Unit Cost Ecomomic'!N4),0),0) -> 189 | H8: =ROUND(E8-$D$3-G8,0) -> 98 | I8: =ROUND(H8*C8,0) -> 11956
A9: ='April-June Unit Cost Ecomomic'!B5 -> Babyâ€™s first handprint and footprint kit | B9: =IF(ISNUMBER('April-June Unit Cost Ecomomic'!E5),'April-June Unit Cost Ecomomic'!E5,"n/a") -> 649 | C9: =IFERROR(N('April-June Unit Cost Ecomomic'!R5),0) -> 160 | D9: =IFERROR(N('April-June Unit Cost Ecomomic'!D5),0) -> 113540 | E9: =ROUND(IFERROR(N('April-June Unit Cost Ecomomic'!K5),0),0) -> 467 | F9: =IFERROR(E9/(D9/C9),0) -> 0.65809406 | G9: =ROUND(IFERROR(N('April-June Unit Cost Ecomomic'!N5),0),0) -> 171 | H9: =ROUND(E9-$D$3-G9,0) -> -299 | I9: =ROUND(H9*C9,0) -> -47840
A10: ='April-June Unit Cost Ecomomic'!B6 -> Mini Starter Finger Painting Fun Pack | B10: =IF(ISNUMBER('April-June Unit Cost Ecomomic'!E6),'April-June Unit Cost Ecomomic'!E6,"n/a") -> 599 | C10: =IFERROR(N('April-June Unit Cost Ecomomic'!R6),0) -> 171 | D10: =IFERROR(N('April-June Unit Cost Ecomomic'!D6),0) -> 101319 | E10: =ROUND(IFERROR(N('April-June Unit Cost Ecomomic'!K6),0),0) -> 407 | F10: =IFERROR(E10/(D10/C10),0) -> 0.68690966 | G10: =ROUND(IFERROR(N('April-June Unit Cost Ecomomic'!N6),0),0) -> 176 | H10: =ROUND(E10-$D$3-G10,0) -> -364 | I10: =ROUND(H10*C10,0) -> -62244
A11: ='April-June Unit Cost Ecomomic'!B10 -> Dabble Starter Painting + Chubby Brush Combo Kit | B11: =IF(ISNUMBER('April-June Unit Cost Ecomomic'!E10),'April-June Unit Cost Ecomomic'!E10,"n/a") -> 1048 | C11: =IFERROR(N('April-June Unit Cost Ecomomic'!R10),0) -> 90 | D11: =IFERROR(N('April-June Unit Cost Ecomomic'!D10),0) -> 90842 | E11: =ROUND(IFERROR(N('April-June Unit Cost Ecomomic'!K10),0),0) -> 706 | F11: =IFERROR(E11/(D11/C11),0) -> 0.6994562 | G11: =ROUND(IFERROR(N('April-June Unit Cost Ecomomic'!N10),0),0) -> 142 | H11: =ROUND(E11-$D$3-G11,0) -> -31 | I11: =ROUND(H11*C11,0) -> -2790
A12: ='April-June Unit Cost Ecomomic'!B9 -> Little Artist Combo Kit | B12: =IF(ISNUMBER('April-June Unit Cost Ecomomic'!E9),'April-June Unit Cost Ecomomic'!E9,"n/a") -> 1797 | C12: =IFERROR(N('April-June Unit Cost Ecomomic'!R9),0) -> 47 | D12: =IFERROR(N('April-June Unit Cost Ecomomic'!D9),0) -> 81477 | E12: =ROUND(IFERROR(N('April-June Unit Cost Ecomomic'!K9),0),0) -> 1233 | F12: =IFERROR(E12/(D12/C12),0) -> 0.71125594 | G12: =ROUND(IFERROR(N('April-June Unit Cost Ecomomic'!N9),0),0) -> 171 | H12: =ROUND(E12-$D$3-G12,0) -> 467 | I12: =ROUND(H12*C12,0) -> 21949
A13: ='April-June Unit Cost Ecomomic'!B15 -> Masterpiece Set | B13: =IF(ISNUMBER('April-June Unit Cost Ecomomic'!E15),'April-June Unit Cost Ecomomic'!E15,"n/a") -> 2047 | C13: =IFERROR(N('April-June Unit Cost Ecomomic'!R15),0) -> 41 | D13: =IFERROR(N('April-June Unit Cost Ecomomic'!D15),0) -> 80419 | E13: =ROUND(IFERROR(N('April-June Unit Cost Ecomomic'!K15),0),0) -> 1372 | F13: =IFERROR(E13/(D13/C13),0) -> 0.69948644 | G13: =ROUND(IFERROR(N('April-June Unit Cost Ecomomic'!N15),0),0) -> 241 | H13: =ROUND(E13-$D$3-G13,0) -> 536 | I13: =ROUND(H13*C13,0) -> 21976
A14: ='April-June Unit Cost Ecomomic'!B7 -> Babyâ€™s Starter Painting + Jumbo Brush Combo Kit | B14: =IF(ISNUMBER('April-June Unit Cost Ecomomic'!E7),'April-June Unit Cost Ecomomic'!E7,"n/a") -> 1098 | C14: =IFERROR(N('April-June Unit Cost Ecomomic'!R7),0) -> 75 | D14: =IFERROR(N('April-June Unit Cost Ecomomic'!D7),0) -> 79281 | E14: =ROUND(IFERROR(N('April-June Unit Cost Ecomomic'!K7),0),0) -> 796 | F14: =IFERROR(E14/(D14/C14),0) -> 0.75301775 | G14: =ROUND(IFERROR(N('April-June Unit Cost Ecomomic'!N7),0),0) -> 154 | H14: =ROUND(E14-$D$3-G14,0) -> 47 | I14: =ROUND(H14*C14,0) -> 3525
A15: ='April-June Unit Cost Ecomomic'!B8 -> Dabble Playart Chunkies | B15: =IF(ISNUMBER('April-June Unit Cost Ecomomic'!E8),'April-June Unit Cost Ecomomic'!E8,"n/a") -> 549 | C15: =IFERROR(N('April-June Unit Cost Ecomomic'!R8),0) -> 129 | D15: =IFERROR(N('April-June Unit Cost Ecomomic'!D8),0) -> 70821 | E15: =ROUND(IFERROR(N('April-June Unit Cost Ecomomic'!K8),0),0) -> 389 | F15: =IFERROR(E15/(D15/C15),0) -> 0.70856102 | G15: =ROUND(IFERROR(N('April-June Unit Cost Ecomomic'!N8),0),0) -> 97 | H15: =ROUND(E15-$D$3-G15,0) -> -303 | I15: =ROUND(H15*C15,0) -> -39087
A16: ='April-June Unit Cost Ecomomic'!B11 -> Dabble Finger Paints For Toddlers | B16: =IF(ISNUMBER('April-June Unit Cost Ecomomic'!E11),'April-June Unit Cost Ecomomic'!E11,"n/a") -> 649 | C16: =IFERROR(N('April-June Unit Cost Ecomomic'!R11),0) -> 101 | D16: =IFERROR(N('April-June Unit Cost Ecomomic'!D11),0) -> 63589 | E16: =ROUND(IFERROR(N('April-June Unit Cost Ecomomic'!K11),0),0) -> 473 | F16: =IFERROR(E16/(D16/C16),0) -> 0.75127774 | G16: =ROUND(IFERROR(N('April-June Unit Cost Ecomomic'!N11),0),0) -> 139 | H16: =ROUND(E16-$D$3-G16,0) -> -261 | I16: =ROUND(H16*C16,0) -> -26361
A17: ='April-June Unit Cost Ecomomic'!B20 -> My Dabble ABC Trace & Colour Kit | Multi-Sensory Alphabet Learning for Kids | B17: =IF(ISNUMBER('April-June Unit Cost Ecomomic'!E20),'April-June Unit Cost Ecomomic'!E20,"n/a") -> 699 | C17: =IFERROR(N('April-June Unit Cost Ecomomic'!R20),0) -> 98 | D17: =IFERROR(N('April-June Unit Cost Ecomomic'!D20),0) -> 58562 | E17: =ROUND(IFERROR(N('April-June Unit Cost Ecomomic'!K20),0),0) -> 476 | F17: =IFERROR(E17/(D17/C17),0) -> 0.79655749 | G17: =ROUND(IFERROR(N('April-June Unit Cost Ecomomic'!N20),0),0) -> 0 | H17: =ROUND(E17-$D$3-G17,0) -> -119 | I17: =ROUND(H17*C17,0) -> -11662
A18: ='April-June Unit Cost Ecomomic'!B21 -> Dabble Playart Finger Paints | B18: =IF(ISNUMBER('April-June Unit Cost Ecomomic'!E21),'April-June Unit Cost Ecomomic'!E21,"n/a") -> 899 | C18: =IFERROR(N('April-June Unit Cost Ecomomic'!R21),0) -> 60 | D18: =IFERROR(N('April-June Unit Cost Ecomomic'!D21),0) -> 53295 | E18: =ROUND(IFERROR(N('April-June Unit Cost Ecomomic'!K21),0),0) -> 628 | F18: =IFERROR(E18/(D18/C18),0) -> 0.70700816 | G18: =ROUND(IFERROR(N('April-June Unit Cost Ecomomic'!N21),0),0) -> 199 | H18: =ROUND(E18-$D$3-G18,0) -> -166 | I18: =ROUND(H18*C18,0) -> -9960
A19: ='April-June Unit Cost Ecomomic'!B12 -> Dabble Art Roll | B19: =IF(ISNUMBER('April-June Unit Cost Ecomomic'!E12),'April-June Unit Cost Ecomomic'!E12,"n/a") -> 699 | C19: =IFERROR(N('April-June Unit Cost Ecomomic'!R12),0) -> 72 | D19: =IFERROR(N('April-June Unit Cost Ecomomic'!D12),0) -> 50328 | E19: =ROUND(IFERROR(N('April-June Unit Cost Ecomomic'!K12),0),0) -> 447 | F19: =IFERROR(E19/(D19/C19),0) -> 0.63948498 | G19: =ROUND(IFERROR(N('April-June Unit Cost Ecomomic'!N12),0),0) -> 145 | H19: =ROUND(E19-$D$3-G19,0) -> -293 | I19: =ROUND(H19*C19,0) -> -21096
A20: ='April-June Unit Cost Ecomomic'!B13 -> Magic Paint Dust + Jumbo Brush Combo Kit â€“ Babyâ€™s First Painting Kit | B20: =IF(ISNUMBER('April-June Unit Cost Ecomomic'!E13),'April-June Unit Cost Ecomomic'!E13,"n/a") -> 1398 | C20: =IFERROR(N('April-June Unit Cost Ecomomic'!R13),0) -> 34 | D20: =IFERROR(N('April-June Unit Cost Ecomomic'!D13),0) -> 45782 | E20: =ROUND(IFERROR(N('April-June Unit Cost Ecomomic'!K13),0),0) -> 975 | F20: =IFERROR(E20/(D20/C20),0) -> 0.7240837 | G20: =ROUND(IFERROR(N('April-June Unit Cost Ecomomic'!N13),0),0) -> 145 | H20: =ROUND(E20-$D$3-G20,0) -> 235 | I20: =ROUND(H20*C20,0) -> 7990
A21: ='April-June Unit Cost Ecomomic'!B19 -> Dabble Painting Art Apron | B21: =IF(ISNUMBER('April-June Unit Cost Ecomomic'!E19),'April-June Unit Cost Ecomomic'!E19,"n/a") -> 799 | C21: =IFERROR(N('April-June Unit Cost Ecomomic'!R19),0) -> 50 | D21: =IFERROR(N('April-June Unit Cost Ecomomic'!D19),0) -> 38751.5 | E21: =ROUND(IFERROR(N('April-June Unit Cost Ecomomic'!K19),0),0) -> 444 | F21: =IFERROR(E21/(D21/C21),0) -> 0.57288105 | G21: =ROUND(IFERROR(N('April-June Unit Cost Ecomomic'!N19),0),0) -> 110 | H21: =ROUND(E21-$D$3-G21,0) -> -261 | I21: =ROUND(H21*C21,0) -> -13050
A22: ='April-June Unit Cost Ecomomic'!B16 -> Magic Paint Dust + PlayArt Roll â€“ Babyâ€™s First Painting Kit | B22: =IF(ISNUMBER('April-June Unit Cost Ecomomic'!E16),'April-June Unit Cost Ecomomic'!E16,"n/a") -> 1598 | C22: =IFERROR(N('April-June Unit Cost Ecomomic'!R16),0) -> 25 | D22: =IFERROR(N('April-June Unit Cost Ecomomic'!D16),0) -> 38622 | E22: =ROUND(IFERROR(N('April-June Unit Cost Ecomomic'!K16),0),0) -> 1055 | F22: =IFERROR(E22/(D22/C22),0) -> 0.68290094 | G22: =ROUND(IFERROR(N('April-June Unit Cost Ecomomic'!N16),0),0) -> 250 | H22: =ROUND(E22-$D$3-G22,0) -> 210 | I22: =ROUND(H22*C22,0) -> 5250
A23: ='April-June Unit Cost Ecomomic'!B29 -> My First Shape Explorer Stamp Kit | B23: =IF(ISNUMBER('April-June Unit Cost Ecomomic'!E29),'April-June Unit Cost Ecomomic'!E29,"n/a") -> 999 | C23: =IFERROR(N('April-June Unit Cost Ecomomic'!R29),0) -> 37 | D23: =IFERROR(N('April-June Unit Cost Ecomomic'!D29),0) -> 36963 | E23: =ROUND(IFERROR(N('April-June Unit Cost Ecomomic'!K29),0),0) -> 551 | F23: =IFERROR(E23/(D23/C23),0) -> 0.55155155 | G23: =ROUND(IFERROR(N('April-June Unit Cost Ecomomic'!N29),0),0) -> 138 | H23: =ROUND(E23-$D$3-G23,0) -> -182 | I23: =ROUND(H23*C23,0) -> -6734
A24: ='April-June Unit Cost Ecomomic'!B25 -> Preschool Art and Craft Kit | B24: =IF(ISNUMBER('April-June Unit Cost Ecomomic'!E25),'April-June Unit Cost Ecomomic'!E25,"n/a") -> 599 | C24: =IFERROR(N('April-June Unit Cost Ecomomic'!R25),0) -> 61 | D24: =IFERROR(N('April-June Unit Cost Ecomomic'!D25),0) -> 35911 | E24: =ROUND(IFERROR(N('April-June Unit Cost Ecomomic'!K25),0),0) -> 341 | F24: =IFERROR(E24/(D24/C24),0) -> 0.57923756 | G24: =ROUND(IFERROR(N('April-June Unit Cost Ecomomic'!N25),0),0) -> 122 | H24: =ROUND(E24-$D$3-G24,0) -> -376 | I24: =ROUND(H24*C24,0) -> -22936
A25: ='April-June Unit Cost Ecomomic'!B42 -> Dabble Baby's First Big Colouring Pages | B25: =IF(ISNUMBER('April-June Unit Cost Ecomomic'!E42),'April-June Unit Cost Ecomomic'!E42,"n/a") -> 399 | C25: =IFERROR(N('April-June Unit Cost Ecomomic'!R42),0) -> 37 | D25: =IFERROR(N('April-June Unit Cost Ecomomic'!D42),0) -> 32903 | E25: =ROUND(IFERROR(N('April-June Unit Cost Ecomomic'!K42),0),0) -> 266 | F25: =IFERROR(E25/(D25/C25),0) -> 0.29912166 | G25: =ROUND(IFERROR(N('April-June Unit Cost Ecomomic'!N42),0),0) -> 146 | H25: =ROUND(E25-$D$3-G25,0) -> -475 | I25: =ROUND(H25*C25,0) -> -17575
A26: ='April-June Unit Cost Ecomomic'!B26 -> My First Dabble Swinginâ€™ Jungle Adventure + Mini Starter Fun Pack + Chubby Brushes Combo | B26: =IF(ISNUMBER('April-June Unit Cost Ecomomic'!E26),'April-June Unit Cost Ecomomic'!E26,"n/a") -> 1547 | C26: =IFERROR(N('April-June Unit Cost Ecomomic'!R26),0) -> 21 | D26: =IFERROR(N('April-June Unit Cost Ecomomic'!D26),0) -> 31366 | E26: =ROUND(IFERROR(N('April-June Unit Cost Ecomomic'!K26),0),0) -> 1067 | F26: =IFERROR(E26/(D26/C26),0) -> 0.71437225 | G26: =ROUND(IFERROR(N('April-June Unit Cost Ecomomic'!N26),0),0) -> 134 | H26: =ROUND(E26-$D$3-G26,0) -> 338 | I26: =ROUND(H26*C26,0) -> 7098
A27: ='April-June Unit Cost Ecomomic'!B30 -> Sensory Discovery Kit | Dabble Sensory Rice + Sensory Play Dough | B27: =IF(ISNUMBER('April-June Unit Cost Ecomomic'!E30),'April-June Unit Cost Ecomomic'!E30,"n/a") -> 1598 | C27: =IFERROR(N('April-June Unit Cost Ecomomic'!R30),0) -> 20 | D27: =IFERROR(N('April-June Unit Cost Ecomomic'!D30),0) -> 30792 | E27: =ROUND(IFERROR(N('April-June Unit Cost Ecomomic'!K30),0),0) -> 1115 | F27: =IFERROR(E27/(D27/C27),0) -> 0.72421408 | G27: =ROUND(IFERROR(N('April-June Unit Cost Ecomomic'!N30),0),0) -> 157 | H27: =ROUND(E27-$D$3-G27,0) -> 363 | I27: =ROUND(H27*C27,0) -> 7260
A28: ='April-June Unit Cost Ecomomic'!B14 -> My First Dabble Swinginâ€™ Jungle Adventure + Crayons Combo | B28: =IF(ISNUMBER('April-June Unit Cost Ecomomic'!E14),'April-June Unit Cost Ecomomic'!E14,"n/a") -> 948 | C28: =IFERROR(N('April-June Unit Cost Ecomomic'!R14),0) -> 29 | D28: =IFERROR(N('April-June Unit Cost Ecomomic'!D14),0) -> 26411 | E28: =ROUND(IFERROR(N('April-June Unit Cost Ecomomic'!K14),0),0) -> 641 | F28: =IFERROR(E28/(D28/C28),0) -> 0.70383552 | G28: =ROUND(IFERROR(N('April-June Unit Cost Ecomomic'!N14),0),0) -> 139 | H28: =ROUND(E28-$D$3-G28,0) -> -93 | I28: =ROUND(H28*C28,0) -> -2697
A29: ='April-June Unit Cost Ecomomic'!B18 -> Dabble Reusable Colouring Pages Kit | B29: =IF(ISNUMBER('April-June Unit Cost Ecomomic'!E18),'April-June Unit Cost Ecomomic'!E18,"n/a") -> 399 | C29: =IFERROR(N('April-June Unit Cost Ecomomic'!R18),0) -> 67 | D29: =IFERROR(N('April-June Unit Cost Ecomomic'!D18),0) -> 24159.9 | E29: =ROUND(IFERROR(N('April-June Unit Cost Ecomomic'!K18),0),0) -> 275 | F29: =IFERROR(E29/(D29/C29),0) -> 0.76262733 | G29: =ROUND(IFERROR(N('April-June Unit Cost Ecomomic'!N18),0),0) -> 97 | H29: =ROUND(E29-$D$3-G29,0) -> -417 | I29: =ROUND(H29*C29,0) -> -27939
A30: ='April-June Unit Cost Ecomomic'!B27 -> Dabble Playart Crayons | B30: =IF(ISNUMBER('April-June Unit Cost Ecomomic'!E27),'April-June Unit Cost Ecomomic'!E27,"n/a") -> 449 | C30: =IFERROR(N('April-June Unit Cost Ecomomic'!R27),0) -> 52 | D30: =IFERROR(N('April-June Unit Cost Ecomomic'!D27),0) -> 23018 | E30: =ROUND(IFERROR(N('April-June Unit Cost Ecomomic'!K27),0),0) -> 310 | F30: =IFERROR(E30/(D30/C30),0) -> 0.70032149 | G30: =ROUND(IFERROR(N('April-June Unit Cost Ecomomic'!N27),0),0) -> 101 | H30: =ROUND(E30-$D$3-G30,0) -> -386 | I30: =ROUND(H30*C30,0) -> -20072
A31: ='April-June Unit Cost Ecomomic'!B23 -> Dabble Magic Bubbles POP n PLAY | B31: =IF(ISNUMBER('April-June Unit Cost Ecomomic'!E23),'April-June Unit Cost Ecomomic'!E23,"n/a") -> 449 | C31: =IFERROR(N('April-June Unit Cost Ecomomic'!R23),0) -> 48 | D31: =IFERROR(N('April-June Unit Cost Ecomomic'!D23),0) -> 20025.4 | E31: =ROUND(IFERROR(N('April-June Unit Cost Ecomomic'!K23),0),0) -> 304 | F31: =IFERROR(E31/(D31/C31),0) -> 0.72867458 | G31: =ROUND(IFERROR(N('April-June Unit Cost Ecomomic'!N23),0),0) -> 101 | H31: =ROUND(E31-$D$3-G31,0) -> -392 | I31: =ROUND(H31*C31,0) -> -18816
A32: ='April-June Unit Cost Ecomomic'!B28 -> Dabble Sensory Rice Play Kit | B32: =IF(ISNUMBER('April-June Unit Cost Ecomomic'!E28),'April-June Unit Cost Ecomomic'!E28,"n/a") -> 699 | C32: =IFERROR(N('April-June Unit Cost Ecomomic'!R28),0) -> 28 | D32: =IFERROR(N('April-June Unit Cost Ecomomic'!D28),0) -> 19372 | E32: =ROUND(IFERROR(N('April-June Unit Cost Ecomomic'!K28),0),0) -> 495 | F32: =IFERROR(E32/(D32/C32),0) -> 0.71546562 | G32: =ROUND(IFERROR(N('April-June Unit Cost Ecomomic'!N28),0),0) -> 123 | H32: =ROUND(E32-$D$3-G32,0) -> -223 | I32: =ROUND(H32*C32,0) -> -6244
A33: ='April-June Unit Cost Ecomomic'!B22 -> Imagination Spark Kit | Dabble Sensory Play Dough + Magic Paint Dust | B33: =IF(ISNUMBER('April-June Unit Cost Ecomomic'!E22),'April-June Unit Cost Ecomomic'!E22,"n/a") -> 1798 | C33: =IFERROR(N('April-June Unit Cost Ecomomic'!R22),0) -> 11 | D33: =IFERROR(N('April-June Unit Cost Ecomomic'!D22),0) -> 19004 | E33: =ROUND(IFERROR(N('April-June Unit Cost Ecomomic'!K22),0),0) -> 1226 | F33: =IFERROR(E33/(D33/C33),0) -> 0.70964008 | G33: =ROUND(IFERROR(N('April-June Unit Cost Ecomomic'!N22),0),0) -> 158 | H33: =ROUND(E33-$D$3-G33,0) -> 473 | I33: =ROUND(H33*C33,0) -> 5203
A34: ='April-June Unit Cost Ecomomic'!B56 -> Dabble Starter Finger Painting Fun Pack + Apron ComboKit | B34: =IF(ISNUMBER('April-June Unit Cost Ecomomic'!E56),'April-June Unit Cost Ecomomic'!E56,"n/a") -> 1398 | C34: =IFERROR(N('April-June Unit Cost Ecomomic'!R56),0) -> 14 | D34: =IFERROR(N('April-June Unit Cost Ecomomic'!D56),0) -> 18726 | E34: =ROUND(IFERROR(N('April-June Unit Cost Ecomomic'!K56),0),0) -> 848 | F34: =IFERROR(E34/(D34/C34),0) -> 0.63398483 | G34: =ROUND(IFERROR(N('April-June Unit Cost Ecomomic'!N56),0),0) -> 112 | H34: =ROUND(E34-$D$3-G34,0) -> 141 | I34: =ROUND(H34*C34,0) -> 1974
A35: ='April-June Unit Cost Ecomomic'!B32 -> Dabble DIY Sensory Playdough Kit | B35: =IF(ISNUMBER('April-June Unit Cost Ecomomic'!E32),'April-June Unit Cost Ecomomic'!E32,"n/a") -> 599 | C35: =IFERROR(N('April-June Unit Cost Ecomomic'!R32),0) -> 34 | D35: =IFERROR(N('April-June Unit Cost Ecomomic'!D32),0) -> 18643 | E35: =ROUND(IFERROR(N('April-June Unit Cost Ecomomic'!K32),0),0) -> 440 | F35: =IFERROR(E35/(D35/C35),0) -> 0.80244596 | G35: =ROUND(IFERROR(N('April-June Unit Cost Ecomomic'!N32),0),0) -> 135 | H35: =ROUND(E35-$D$3-G35,0) -> -290 | I35: =ROUND(H35*C35,0) -> -9860
A36: ='April-June Unit Cost Ecomomic'!B17 -> Baby's First Art Set | B36: =IF(ISNUMBER('April-June Unit Cost Ecomomic'!E17),'April-June Unit Cost Ecomomic'!E17,"n/a") -> 1248 | C36: =IFERROR(N('April-June Unit Cost Ecomomic'!R17),0) -> 12 | D36: =IFERROR(N('April-June Unit Cost Ecomomic'!D17),0) -> 15345 | E36: =ROUND(IFERROR(N('April-June Unit Cost Ecomomic'!K17),0),0) -> 839 | F36: =IFERROR(E36/(D36/C36),0) -> 0.65610948 | G36: =ROUND(IFERROR(N('April-June Unit Cost Ecomomic'!N17),0),0) -> 345 | H36: =ROUND(E36-$D$3-G36,0) -> -101 | I36: =ROUND(H36*C36,0) -> -1212
A37: ='April-June Unit Cost Ecomomic'!B36 -> Dabble Jumbo Paint Brush Set | B37: =IF(ISNUMBER('April-June Unit Cost Ecomomic'!E36),'April-June Unit Cost Ecomomic'!E36,"n/a") -> 499 | C37: =IFERROR(N('April-June Unit Cost Ecomomic'!R36),0) -> 31 | D37: =IFERROR(N('April-June Unit Cost Ecomomic'!D36),0) -> 14469 | E37: =ROUND(IFERROR(N('April-June Unit Cost Ecomomic'!K36),0),0) -> 337 | F37: =IFERROR(E37/(D37/C37),0) -> 0.7220264 | G37: =ROUND(IFERROR(N('April-June Unit Cost Ecomomic'!N36),0),0) -> 103 | H37: =ROUND(E37-$D$3-G37,0) -> -361 | I37: =ROUND(H37*C37,0) -> -11191
A38: ='April-June Unit Cost Ecomomic'!B68 -> Canvas and Stand | B38: =IF(ISNUMBER('April-June Unit Cost Ecomomic'!E68),'April-June Unit Cost Ecomomic'!E68,"n/a") -> 160 | C38: =IFERROR(N('April-June Unit Cost Ecomomic'!R68),0) -> 105 | D38: =IFERROR(N('April-June Unit Cost Ecomomic'!D68),0) -> 14112 | E38: =ROUND(IFERROR(N('April-June Unit Cost Ecomomic'!K68),0),0) -> 129 | F38: =IFERROR(E38/(D38/C38),0) -> 0.95982143 | G38: =ROUND(IFERROR(N('April-June Unit Cost Ecomomic'!N68),0),0) -> 104 | H38: =ROUND(E38-$D$3-G38,0) -> -570 | I38: =ROUND(H38*C38,0) -> -59850
A39: ='April-June Unit Cost Ecomomic'!B39 -> Creative Wonder Set | Dabble Play Art Chunkies + Sensory Play Dough | B39: =IF(ISNUMBER('April-June Unit Cost Ecomomic'!E39),'April-June Unit Cost Ecomomic'!E39,"n/a") -> 1448 | C39: =IFERROR(N('April-June Unit Cost Ecomomic'!R39),0) -> 10 | D39: =IFERROR(N('April-June Unit Cost Ecomomic'!D39),0) -> 13926 | E39: =ROUND(IFERROR(N('April-June Unit Cost Ecomomic'!K39),0),0) -> 1007 | F39: =IFERROR(E39/(D39/C39),0) -> 0.72310786 | G39: =ROUND(IFERROR(N('April-June Unit Cost Ecomomic'!N39),0),0) -> 151 | H39: =ROUND(E39-$D$3-G39,0) -> 261 | I39: =ROUND(H39*C39,0) -> 2610
A40: ='April-June Unit Cost Ecomomic'!B31 -> Toddler's First Painting Set | Finger Paints + Jumbo Brushes | B40: =IF(ISNUMBER('April-June Unit Cost Ecomomic'!E31),'April-June Unit Cost Ecomomic'!E31,"n/a") -> 1148 | C40: =IFERROR(N('April-June Unit Cost Ecomomic'!R31),0) -> 12 | D40: =IFERROR(N('April-June Unit Cost Ecomomic'!D31),0) -> 13325 | E40: =ROUND(IFERROR(N('April-June Unit Cost Ecomomic'!K31),0),0) -> 814 | F40: =IFERROR(E40/(D40/C40),0) -> 0.73305816 | G40: =ROUND(IFERROR(N('April-June Unit Cost Ecomomic'!N31),0),0) -> 113 | H40: =ROUND(E40-$D$3-G40,0) -> 106 | I40: =ROUND(H40*C40,0) -> 1272
A41: ='April-June Unit Cost Ecomomic'!B24 -> Dabble Starter Pack | Chunkies + Finger Paints + Art Roll | B41: =IF(ISNUMBER('April-June Unit Cost Ecomomic'!E24),'April-June Unit Cost Ecomomic'!E24,"n/a") -> 1897 | C41: =IFERROR(N('April-June Unit Cost Ecomomic'!R24),0) -> 7 | D41: =IFERROR(N('April-June Unit Cost Ecomomic'!D24),0) -> 12785 | E41: =ROUND(IFERROR(N('April-June Unit Cost Ecomomic'!K24),0),0) -> 1311 | F41: =IFERROR(E41/(D41/C41),0) -> 0.71779429 | G41: =ROUND(IFERROR(N('April-June Unit Cost Ecomomic'!N24),0),0) -> 163 | H41: =ROUND(E41-$D$3-G41,0) -> 553 | I41: =ROUND(H41*C41,0) -> 3871
A42: ='April-June Unit Cost Ecomomic'!B37 -> Dabble Dessert Party Pretend Playdough Set | B42: =IF(ISNUMBER('April-June Unit Cost Ecomomic'!E37),'April-June Unit Cost Ecomomic'!E37,"n/a") -> 599 | C42: =IFERROR(N('April-June Unit Cost Ecomomic'!R37),0) -> 22 | D42: =IFERROR(N('April-June Unit Cost Ecomomic'!D37),0) -> 12172 | E42: =ROUND(IFERROR(N('April-June Unit Cost Ecomomic'!K37),0),0) -> 415 | F42: =IFERROR(E42/(D42/C42),0) -> 0.75008216 | G42: =ROUND(IFERROR(N('April-June Unit Cost Ecomomic'!N37),0),0) -> 84 | H42: =ROUND(E42-$D$3-G42,0) -> -264 | I42: =ROUND(H42*C42,0) -> -5808
...
